Workbook

Sheet Fixation 
A1: evsjv‡`k †U·UvBj wek¦we`¨vjq A_© I wnmve `ßi ‡ZRMuvI, XvKv - 1208|
A3: Gm.Avi.I bs 348-AvBb/2026, ZvwiL -17-9-2026 RvZxq †eZb †¯‹j 2026 Abyhvqx †eZb wba©vibx weeiYx t
B5: AvBwW | D5: 218 | F5: 1g †MÖW | G5: 2q †MÖW | H5: 3q †MÖW | I5: 4_© †MÖW | J5: 5g †MÖW | K5: 6ó †MÖW | L5: 7g †MÖW | M5: 8g †MÖW | N5: 9g †MÖW
A6: 1 | B6: bvg | C6: t | D6: =VLOOKUP(D5,Inforation!A2:G412,2,FALSE) -> ‡gvt mvnv`vZ †nv‡mb | F6: 156000 | G6: 132000 | H6: 113000 | I6: 100000 | J6: 86000 | K6: 71000 | L6: 58000 | M6: 46000 | N6: 44000
A7: 2 | B7: eZ©gvb c` (30-06-2026) | C7: t | D7: =VLOOKUP(D6,Inforation!B2:G412,2,FALSE) -> †mKkb Awdmvi | G7: 135700 | H7: 117000 | I7: 103500 | J7: 89500 | K7: 74600 | L7: 60900 | M7: 48300 | N7: 46200
A8: 3 | B8: ey‡U· G †hvM`v‡bi ZvwiL | C8: t | G8: 139400 | H8: 121100 | I8: 107200 | J8: 93100 | K8: 78300 | L8: 64000 | M8: 50800 | N8: 48600
A9: 4 | B9: wefvM/`ßi | C9: t | D9: =VLOOKUP(D6,Inforation!B2:G412,3,FALSE) -> A_© I wnmve | G9: 147200 | H9: 129700 | I9: 110900 | J9: 96800 | K9: 82200 | L9: 67200 | M9: 53300 | N9: 51000
A10: 5 | B10: ‡mj †dvb bs | C10: t | D10: =VLOOKUP(D6,Inforation!B2:G413,4,FALSE) -> 0 | G10: 151200 | H10: 134300 | I10: 114800 | J10: 100700 | K10: 86400 | L10: 70500 | M10: 56000 | N10: 53500
A11: 6 | B11: RvZxq cwiPq cÎ bs | C11: t | D11: =VLOOKUP(D6,Inforation!B2:G414,5,FALSE) -> 0124100063454 | G11: 153000 | H11: 139000 | I11: 118800 | J11: 104700 | K11: 90700 | L11: 74100 | M11: 58800 | N11: 56200
A12: 8 | B12: RvZxq †eZb †¯‹j 2015 Abyhvqx 30 Ryb 2026 Zvwi‡L M„nxZ †eZb | C12: t | D12: =VLOOKUP('Fixation '!D6,Inforation!B2:G413,6,FALSE) -> 28100 | H12: 143800 | I12: 123000 | J12: 108900 | K12: 95200 | L12: 77800 | M12: 61700 | N12: 59000
A13: 9 | B13: RvZxq †eZb †¯‹j 2015 Abyhvqx 30 Ryb 2026 Zvwi‡L | C13: t | H13: 148800 | I13: 127300 | J13: 113200 | K13: 100000 | L13: 81700 | M13: 64800 | N13: 62000
B14: K) cÖvß †MÖW/D”PZi †MÖW I ‡¯‹j | C14: t | D14: গ্রেড - ৯ | E14: 22000-53060 | I14: 131700 | J14: 117700 | K14: 104900 | L14: 85700 | M14: 68000 | N14: 65100
B15: L) cÖvß †MÖW/D”PZi †MÖ‡Wi cÖviw¤¢K ‡eZb | C15: t | D15: 22000 | E15: ** | I15: 136300 | J15: 122500 | K15: 110200 | L15: 90000 | M15: 71400 | N15: 68300
A16: 10 | B16: cv_©K¨ (8-9L) | C16: t | D16: =D12-D15 -> 6100 | I16: 142400 | J16: 127400 | K16: 115700 | L16: 94500 | M16: 75000 | N16: 71700
A17: 11 | B17: RvZxq †eZb †¯‹j 2026 Abyhvqx 01/07/2026 Zvwi‡L | C17: t | J17: 132400 | K17: 121500 | L17: 99200 | M17: 78700 | N17: 75300
B18: K) cÖvc¨ †MÖW/D”PZi †MÖW I ‡¯‹j | C18: t | D18: গ্রেড - ৯ | E18: 44000-105900 | J18: 139700 | K18: 127600 | L18: 104200 | M18: 82700 | N18: 79100
B19: L) cÖvc¨ †MÖW/D”&PZi †MÖ‡Wi cÖviw¤¢K ‡eZb | C19: t | D19: 44000 | E19: ** | K19: 134000 | L19: 109400 | M19: 86800 | N19: 83000
A20: 12 | B20: ‡gvU †eZb (10+11L) | C20: t | D20: =D16+D19 -> 50100 | L20: 114900 | M20: 91100 | N20: 87200
A21: 13 | B21: 01/07/2026 Zvwi‡L cÖvc¨ †eZ‡bi avc (†eZb †¯‹j 2026) | C21: t | D21: 51000 | E21: ** | L21: 120600 | M21: 95700 | N21: 91500
A22: 14 | B22: 01/07/2026 Zvwi‡L evwl©K †eZb e„w× (Bbwµ‡g›U) mn †eZb [RvZxq †eZb †¯‹j-2026 Gi 8(2) aviv †gvZv‡eK] | C22: t | D22: 53500 | E22: ** | L22: 126800 | M22: 100500 | N22: 96100
A23: 15 | B23: ‡eZb e„w×i cwigvY (13-8) | C23: t | D23: =D21-D12 -> 22900 | M23: 105500 | N23: 100900
A24: 16 | B24: 01/07/2026 Zvwi‡L e„w× cÖvß †eZ‡bi (Kjvg 15 Abymv‡i) | C24: t | M24: 110800 | N24: 105900
B25: K) 40% (1g n‡Z 9g †Mª‡Wi Rb¨) | C25: t | D25: =D23*40% -> 9160
B26: L) 50% (10g †MÖW n‡Z 20 Zg †Mª‡Wi Rb¨) | C26: t
A27: 17 | B27: 01/01/2027 Zvwi‡L e„w× cÖvß †eZ‡bi (Kjvg 15 Abymv‡i) | C27: t
B28: K) cieZx© 70% (1g n‡Z 9g †Mª‡Wi Rb¨) | C28: t | D28: =D23*70% -> 16030
B29: L) cieZx© 75% (10g †MÖW n‡Z 20 Zg †Mª‡Wi Rb¨) | C29: t
A30: 18 | B30: 01/07/2026 Zvwi‡L wba©vwiZ †eZb (8+16) | C30: t | D30: =D12+D25 -> 37260
A31: 19 | B31: 01/07/2026 Zvwi‡L evwl©K †eZb e„w×i nvi (14 bs - 13 bs) | C31: t | D31: =D22-D21 -> 2500 | G31: =53500-51000 -> 2500
A32: 20 | B32: 01/07/2026 Zvwi‡L evwl©K †eZb e„w× mn cÖvc¨ †eZb (8+16+19) | C32: t | D32: =D12+D25+D31 -> 39760
A33: 21 | B33: 01/01/2027 Zvwi‡L evwl©K †eZb e„w× mn cÖvc¨ †eZb (8+17+19) | C33: t | D33: =D12+D28+D31 -> 46630
A34: 22 | B34: 01/07/2026 Zvwi‡L wbavwiZ †eZb 100% | C34: t | D34: =D22 -> 53500
A35: 23 | B35: 01/7/2027 Zvwi‡L evwl©K †eZb e„w× (Bbwµ‡g›U) mn cÖvc&¨ †eZb | C35: t | D35: 56200 | E35: **
A36: 24 | B36: cieZ©x evwl©K †eZb e„wÏi ZvwiL | C36: t | D36: 46759
D39: ---------------------------------
C40: wkÿK/ Kg©KZ©v/Kg©Pvixi ¯^vÿi I mxj
A43: cÖ¯‘ZKviK Dc-cwiPvjK(m¨vjvwi) | D43: cwiPvjK (A_© I wnmve)
B45: AwWU Awd‡mi e¨env‡ii Rb¨
A46: D³ †eZb weeibx wbixÿv Kiv nBj| RvZxq †eZb †¯‹j 2026 Abyhvqx wb¤œiæcfv‡e †eZb wba©viY Kiv n‡jv
A47: 1 | B47: K) 1 RyjvB 2026 Zvwi‡L wba©vwiZ †eZb †MÖW | C47: t
...

Sheet Inforation
A1: bs | B1: bvg | C1: c`ex | D1: wefvM/`ßi | E1: ‡gvevBj b¤^i | F1: GbAvBwW bs | G1: g~j †eZb
A2: 1 | B2: Aa¨vcK W. †gvt Ryjnvm DwÏb | C2: fvBm P¨v‡Ýji | D2: fvBm P¨v‡Ýji `ßi | E2: 333333171 | F2: 0124100020088 | G2: 78000
A3: 2 | B3: W. kvn-Avwjgy¾vgvb | C3: Aa¨vcK | D3: †dweªK BwÄwbqvwis | F3: 0124100010352 | G3: 78000
A4: 3 | B4: W. †mL †gvt gwgbyj Avjg | C4: Aa¨vcK | D4: ‡U·: †gwkbvwi wWRvBb GÛ ‡gBb | F4: 0124100040385 | G4: 78000
A5: 4 | B5: W. †gvt gwkDi ingvb Lvub | C5: Aa¨vcK | D5: G¨vcv‡ij BwÄwbqvwis | F5: 0124100022027 | G5: 78000
A6: 5 | B6: W. †nvm‡b Aviv †eMg | C6: Aa¨vcK | D6: BqvY© BwÄwbqvwis | F6: 0124100023603 | G6: 76490
A7: 6 | B7: W. bviwMm Rvnvb Aviv | C7: Aa¨vcK | D7: imvqb wefvM | F7: 0124100023956 | G7: 78000
A8: 7 | B8: W. †gvnv¤§` Avjx | C8: Aa¨vcK | D8: AvBwcB | F8: 0124100030692 | G8: 78000
A9: 8 | B9: W. ‡gvt dinv` †nv‡mb | C9: Aa¨vcK | D9: WvBR GÛ †KwgK¨vj BwÄwbqvwis | F9: 0124100067967 | G9: 76490
A10: 9 | B10: W.kidzb bvnvi AviRy | C10: Aa¨vcK | D10: I‡qU cÖ‡mm BwÄwbqvwis | F10: 0124100031398 | G10: 76490
A11: 10 | B11: W. D¤§yj Lv‡qi dv‡Zgv | C11: Aa¨vcK | D11: Gbfvqib †g›Uvj mv‡qÝ | F11: 0124100087074 | G11: 76490
A12: 11 | B12: W.‡gvt gvmyg | C12: Aa¨vcK | D12: †U·UvBj BwÄ: g¨v‡bR‡g›U | F12: 0124100088406 | G12: 76490
A13: 12 | B13: W.†gvt Avnmvb nvexe | C13: Aa¨vcK | D13: †U·UvBj BwÄ: g¨v‡bR‡g›U | F13: 0124100085742 | G13: 68770
A14: 13 | B14: W.†gvt mvwgDj Bmjvg †PŠayix | C14: Aa¨vcK | D14: imvqb | F14: 0124100092373 | G14: 68770
... A20: 19 | B20: iv‡k`v †eMg w`bv | C20: Aa¨vcK | D20: I‡qU cÖ‡mm BwÄwbqvwis | F20: 0124100085035 | G20: 74400
A21: 20 | B21: W.†gvt wiqvRyj Bmjvg | C21: Aa¨vcK | F21: 0124100085762 | G21: 74400
A22: 21 | B22: W.†gvt Bg`v` miKvi | C22: Aa¨vcK | F22: 0124100055557 | G22: 74400
A23: 22 | B23: W.Bgvbv kvnixb Zvwbqv | C23: Aa¨vcK | D23: I‡qU cÖ‡mm BwÄwbqvwis | F23: 0124100091838 | G23: 66120
A24: 23 | B24: W.jvgBqv Rwni | C24: Aa¨vcK | D24: G¨vcv‡ij BwÄwbqvwis | F24: 0124100091697 | G24: 66120
A25: 24 | B25: W.‡gvt gvneyeyi ingvb | C25: Aa¨vcK | D25: d¨vkb GÛ wWRvBb BwÄ: | F25: 0124100067745 | G25: 66120
A26: 25 | B26: W. †kL gvgyb Kwei | C26: Aa¨vcK | D26: I‡qU cÖ‡mm BwÄwbqvwis | F26: 0124100085782 | G26: 66120
A27: 26 | B27: W.†gvt Rvwn`yj Bmjvg | C27: mn‡hvMx Aa¨vcK | D27: ‡dweªK BwÄ. | F27: 0124100053016 | G27: 74400
A28: 27 | B28: W. Zby Av‡idxb | C28: mn‡hvMx Aa¨vcK | F28: 0124100089648 | G28: 68770
A29: 28 | B29: W.G.wU.Gg. d‡qR Avn‡g` | C29: mn‡hvMx Aa¨vcK | F29: 0124801012177 | G29: 66120
A30: 29 | B30: W.‡gvnv¤§` dinv`yi ingvb | C30: mn‡hvMx Aa¨vcK | F30: 0124801012254 | G30: 61120
A31: 30 | B31: W.†gvt byiæb bex | C31: mn‡hvMx Aa¨vcK | F31: 0124801012489 | G31: 61120
A32: 31 | B32: W.‡gvnv¤§` iwdKzj ikx` | C32: mn‡hvMx Aa¨vcK | F32: 0124801014524 | G32: 58760
A33: 32 | B33: m. g. dvinvbv BKevj | C33: mn‡hvMx Aa¨vcK | D33: BqvY© BwÄwbqvwis | F33: 0124100084127 | G33: 65820
A34: 33 | B34: W.Abyc Kzgvi `I | C34: mn‡hvMx Aa¨vcK | D34: MwYZ | F34: 0124100092363 | G34: 56250
A35: 34 | B35: W.‡gvt myjZvb gvngy` | C35: mn‡hvMx Aa¨vcK | D35: BqvY© BwÄwbqvwis | F35: 0124100092041 | G35: 65820
A36: 35 | B36: W. Avey †gvnv¤§` AvRgj †gv‡k©` | C36: mn‡hvMx Aa¨vcK | D36: imvqb | F36: 0124801013402 | G36: 63280
A37: 36 | B37: W.w`jviv †nv‡mb | C37: mn‡hvMx Aa¨vcK | F37: 0124100085893 | G37: 71200
A38: 37 | B38: W.‡gvt iæKby¾vgvb | C38: mn‡hvMx Aa¨vcK | F38: 0124100095844 | G38: 71200
A39: 38 | B39: W.‡gvt iv‡k`yj Bmjvg | C39: mn‡hvMx Aa¨vcK | F39: 0124801013911 | G39: 56250
A40: 39 | B40: gviwRqv `yjvj | C40: mnKvix Aa¨vcK | F40: 0124801013614 | G40: 58500
A41: 40 | B41: W.‡gvnv¤§` AveŸvm D`&`xb | C41: mnKvix Aa¨vcK | F41: 0124801013975 | G41: 60840
A42: 41 | B42: W.Avn‡g` Rvjvj DwÏb | C42: mnKvix Aa¨vcK | F42: 0124801015582 | G42: 58500
A43: 42 | B43: G.Gb.Gg.gvmy`yi ingvb | C43: mnKvix Aa¨vcK | F43: 0124801014146 | G43: 56250
A44: 43 | B44: W.gvn&gy`v Av³vi | C44: Aa¨vcK | D44: G¨vcv‡ij BwÄwbqvwis | F44: 0124100085752 | G44: 71530
A45: 44 | B45: myZcv ‡PŠayix | C45: mn‡hvMx Aa¨vcK | D45: d¨vkb GÛ wWRvBb BwÄ: | F45: 0124100085045
...

Sheet Sheet1
A7: Aa¨vcK
A8: Aa¨vcK W. †gvt Ryjnvm DwÏb fvBm P¨v‡Ýji †¯‹jt 78000/- wefvMt I‡qU cÖ‡mm BwÄwbqvwis
A9: Aa¨vcK W. kvn Avwjgy¾vgvb Aa¨vcK ‡¯‹jt 78000/- wefvMt †dweªK BwÄwbqvwis
A10: Aa¨vcK W. †mL ‡gvt gwgbyj Avjg Aa¨vcK I we:cÖ ‡¯‹jt 78000/- wefvMt ‡U·: †gwkbvwi wWRvBb GÛ ‡gBb
A11: W. ‡gvt gwkDi ingvb Luvb Aa¨vcK I cwiPvjK(wk: Kj¨vb) ‡¯‹jt 78000/- wefvMt G¨vcv‡ij BwÄwbqvwis
A12: W. †nvm‡b Aviv †eMg Aa¨vcK Ges cwiPvjK (M‡elbv I m¤úªmviY) ‡¯‹jt 66000-76490/- wefvMt BqvY© BwÄwbqvwis
A13: W. bviMxm Rvnvb Aviv Aa¨vcK I wefvMxq cÖavY ‡¯‹jt 78000/-
A14: W. †gvnv¤§` Avjx Aa¨vcK Ges we: cÖavb ‡¯‹jt 78000/- wefvMt AvBwcB
A15: W. ‡gvt dinv` †nv‡mb Aa¨vcK I wefvMxq cÖavb ‡¯‹jt 66000-76490/- wefvMt WvBR GÛ †KwgK¨vj BwÄwbqvwis
A16: W.kidzb bvnvi AviRy Aa¨vcK I cwiPvjK GwµWvB‡UW ‡¯‹jt 66000-76490/- wefvMt I‡qU cÖ‡mm BwÄwbqvwis
A17: W. D¤§yj Lv‡qi dv‡Zgv Aa¨vcK I wefvMxq cÖavb ‡¯‹jt 66000-76490/- wefvMt Gbfvqib †g›Uvj mv‡qÝ
A18: W.‡gvt gvmyg Aa¨vcK I wefvMxq cÖavb ‡¯‹jt 56500-74400/- wefvMt †U·UvBj BwÄ: g¨v‡bR‡g›U
... A422: ‡gvt ûgvqyb Kwei wmwKDwiwU MvW© †¯‹jt 8250-20010/- †hvM`vbt 29/04/2026

Sheet Sheet2
B1: evsjv‡`k †U·UvBj wek¦we`¨vjq
B2: ‡ZRMuvI, XvKv-1208|
B3: wkÿK‡`i †eZb fvZvi wej Ryb - 2026|
B7: µtbs | D7: bvg I c`ex | H7: cÖvwß mg~n | S7: KZ©b mg~n | AH7: bxU `vex | AI7: gšÍe¨
E8: bvg | F8: c`ex | G8: wnmve bs | H8: g~j‡eZb | I8: we‡kl myweav | J8: evoxfvov fvZv | K8: wPwKrmv fvZv | L8: Avc¨vqb/ we‡kl fvZv | M8: `vwqZ¡fvi fvZv | P8: †Uwj‡dvb /†gvevBj fvZv | Q8: wk¶v mnvqK fvZv | R8: †gvU †eZb | S8: wRwc dvÛ Puv`v | U8: Kj¨vY Znwej | V8: ‡hŠ_ exgv | W8: evox fvov | X8: M¨vm wej | Y8: cvwb I cqtKi | Z8: ‡cŠi Ki | AA8: we`y¨r wej | AB8: Mvox fvov/Kvi PvR© | AC8: AvqKi | AD8: mwgwZi Puv`v | AE8: ivR¯^ ÷¨v¤ú | AF8: 1 w`‡bi †eZb KZ©b/ †W †Kqvi Gi Rb¨ KZ©b | AG8: ‡gvU KZ©b
S9: Puv`v | T9: AwMÖg cÖZ¨vnvi
C10: ‡KvW bs | D10: Aa¨vcK | S10: Puv`v | T10: AwMÖg cÖZ¨vnvi
B11: 1 | C11: 100002 | D11: Aa¨vcK W. †gvt Ryjnvm DwÏb fvBm P¨v‡Ýji †¯‹jt 78000/- wefvMt I‡qU cÖ‡mm BwÄwbqvwis | E11: Aa¨vcK W. †gvt Ryjnvm DwÏb | F11: fvBm P¨v‡Ýji | G11: 0124100020088 | H11: 78000 | I11: =ROUND((H11*10%),0) -> 7800 | K11: 1500 | P11: 4300 | Q11: 500 | R11: =SUM(H11:Q11) -> 92100 | S11: =ROUND((H11*10%),0) -> 7800 | U11: =ROUND((H11*1%),0) -> 780 | AB11: 800 | AC11: 2321 | AD11: 100 | AE11: 10 | AG11: =SUM(S11:AF11) -> 11811 | AH11: =R11-AG11 -> 80289 | AI11: cÖvwaKvi Mvox
B12: 2 | C12: 100004 | D12: Aa¨vcK W. kvn Avwjgy¾vgvb Aa¨vcK ‡¯‹jt 78000/- wefvMt †dweªK BwÄwbqvwis | E12: W. kvn-Avwjgy¾vgvb | F12: Aa¨vcK | G12: 0124100010352 | H12: 78000 | I12: =ROUND((H12*10%),0) -> 7800 | J12: =H12*50% -> 39000 | K12: 1500 | P12: 4300 | Q12: 500 | R12: =SUM(H12:Q12) -> 131100 | S12: =ROUND((H12*10%),0) -> 7800 | U12: =ROUND((H12*1%),0) -> 780 | AC12: 2321 | AD12: 100 | AE12: 10 | AG12: =SUM(S12:AF12) -> 11011 | AH12: =R12-AG12 -> 120089
B13: 3 | C13: 100005 | D13: Aa¨vcK W. †mL ‡gvt gwgbyj Avjg Aa¨vcK I we:cÖ ‡¯‹jt 78000/- wefvMt ‡U·: †gwkbvwi wWRvBb GÛ ‡gBb | E13: W. †mL †gvt gwgbyj Avjg | F13: Aa¨vcK | G13: 0124100040385 | H13: 78000 | I13: =ROUND((H13*10%),0) -> 7800 | J13: 0 | K13: 1500 | M13: =ROUND((H13*12.5%),0) -> 9750 | P13: 4300 | R13: =SUM(H13:Q13) -> 101350 | S13: =ROUND((H13*10%),0) -> 7800 | U13: =ROUND((H13*1%),0) -> 780 | X13: 1080 | Y13: 120 | Z13: 30 | AA13: 6395 | AC13: 2123 | AD13: 100 | AE13: 10 | AG13: =SUM(S13:AF13) -> 18438 | AH13: =R13-AG13 -> 82912
B14: 4 | C14: 100006 | D14: W. ‡gvt gwkDi ingvb Luvb Aa¨vcK I cwiPvjK(wk: Kj¨vb) ‡¯‹jt 78000/- wefvMt G¨vcv‡ij BwÄwbqvwis | E14: W. †gvt gwkDi ingvb Lvub | F14: Aa¨vcK | G14: 0124100022027 | H14: 78000 | I14: =ROUND((H14*10%),0) -> 7800 | J14: =ROUND((H14*50%),0) -> 39000 | K14: 1500 | M14: =ROUND((H14*12.5%),0) -> 9750 | P14: 4300 | Q14: 500 | R14: =SUM(H14:Q14) -> 140850 | S14: =ROUND((H14*10%),0) -> 7800 | T14: 0 | U14: =ROUND((H14*1%),0) -> 780 | AB14: 250 | AC14: 2123 | AD14: 100 | AE14: 10 | AG14: =SUM(S14:AF14) -> 11063 | AH14: =R14-AG14 -> 129787
B15: 5 | C15: 100007 | D15: W. †nvm‡b Aviv †eMg Aa¨vcK Ges cwiPvjK (M‡elbv I m¤úªmviY) ‡¯‹jt 66000-76490/- wefvMt BqvY© BwÄwbqvwis | E15: W. †nvm‡b Aviv †eMg | F15: Aa¨vcK | G15: 0124100023603 | H15: 76490 | I15: =ROUND((H15*10%),0) -> 7649 | J15: =H15*50% -> 38245 | K15: 1500 | M15: =ROUND((H15*12.5%),0) -> 9561 | P15: 4300 | R15: =SUM(H15:Q15) -> 137745 | S15: =ROUND((H15*10%),0) -> 7649 | U15: =ROUND((H15*1%),0) -> 765 | AC15: 3581 | AD15: 100 | AE15: 10 | AG15: =SUM(S15:AF15) -> 12105 | AH15: =R15-AG15 -> 125640
B16: 6 | C16: 100008 | D16: W. bviMxm Rvnvb Aviv Aa¨vcK I wefvMxq cÖavY ‡¯‹jt 78000/- | E16: W. bviwMm Rvnvb Aviv | F16: Aa¨vcK | G16: 0124100023956 | H16: 78000 | I16: =ROUND((H16*10%),0) -> 7800 | J16: =ROUND((H16*50%),0) -> 39000 | K16: 1500 | M16: =ROUND((H16*12.5% /30*4),0) -> 1300 | P16: 4300 | Q16: 1000 | R16: =SUM(H16:Q16) -> 132900 | S16: =ROUND((H16*10%),0) -> 7800 | T16: 0 | U16: =ROUND((H16*1%),0) -> 780 | AB16: 0 | AC16: 3581 | AD16: 100 | AE16: 10 | AG16: =SUM(S16:AF16) -> 12271 | AH16: =R16-AG16 -> 120629 | AJ16: `vwqZ¡fvZv AvMvgxgv‡m wWwjU n‡e |
B17: 7 | C17: 100009 | D17: W. †gvnv¤§` Avjx Aa¨vcK Ges we: cÖavb ‡¯‹jt 78000/- wefvMt AvBwcB | E17: W. †gvnv¤§` Avjx | F17: Aa¨vcK | G17: 0124100030692 | H17: 78000 | I17: =ROUND((H17*10%),0) -> 7800 | K17: 1500 | M17: =ROUND((H17*12.5%),0) -> 9750 | P17: 4300 | Q17: 1000 | R17: =SUM(H17:Q17) -> 102350 | S17: =ROUND((H17*10%),0) -> 7800 | T17: 0 | U17: =ROUND((H17*1%),0) -> 780 | X17: 1080 | Y17: 120 | Z17: 30 | AA17: 1906 | AC17: 4206 | AD17: 100 | AE17: 10 | AG17: =SUM(S17:AF17) -> 16032 | AH17: =R17-AG17 -> 86318
B18: 8 | C18: 100024 | D18: W. ‡gvt dinv` †nv‡mb Aa¨vcK I wefvMxq cÖavb ‡¯‹jt 66000-76490/- wefvMt WvBR GÛ †KwgK¨vj BwÄwbqvwis | E18: W. ‡gvt dinv` †nv‡mb | F18: Aa¨vcK | G18: 0124100067967 | H18: 76490 | I18: =ROUND((H18*10%),0) -> 7649 | J18: =ROUND((H18*50%),0) -> 38245 | K18: 1500 | M18: =ROUND((H18*12.5%),0) -> 9561 | P18: 4300 | Q18: 1000 | R18: =SUM(H18:Q18) -> 138745 | S18: =ROUND((H18*10%),0) -> 7649 | T18: 23000 | U18: =ROUND((H18*1%),0) -> 765 | AB18: 250 | AC18: 1760 | AD18: 100 | AE18: 10 | AG18: =SUM(S18:AF18) -> 33534 | AH18: =R18-AG18 -> 105211 | AI18: wRwc 14/48
B19: 9 | C19: 100019 | D19: W.kidzb bvnvi AviRy Aa¨vcK I cwiPvjK GwµWvB‡UW ‡¯‹jt 66000-76490/- wefvMt I‡qU cÖ‡mm BwÄwbqvwis | E19: W.kidzb bvnvi AviRy | F19: Aa¨vcK | G19: 0124100031398 | H19: 76490 | I19: =ROUND((H19*10%),0) -> 7649 | J19: =ROUND((H19*50%),0) -> 38245 | K19: 1500 | M19: =ROUND((H19*12.5%),0) -> 9561 | P19: 4300 | Q19: 0 | R19: =SUM(H19:Q19) -> 137745 | S19: =ROUND((H19*10%),0) -> 7649 | T19: 25000 | U19: =ROUND((H19*1%),0) -> 765 | X19: 0 | Y19: 0 | Z19: 0 | AB19: 0 | AC19: 1135 | AD19: 100 | AE19: 10 | AG19: =SUM(S19:AF19) -> 34659 | AH19: =R19-AG19 -> 103086 | AI19: wRwc 22/48
B20: 10 | C20: 100018 | D20: W. D¤§yj Lv‡qi dv‡Zgv Aa¨vcK I wefvMxq cÖavb ‡¯‹jt 66000-76490/- wefvMt Gbfvqib †g›Uvj mv‡qÝ | E20: W. D¤§yj Lv‡qi dv‡Zgv | F20: Aa¨vcK | G20: 0124100087074 | H20: 76490 | I20: =ROUND((H20*10%),0) -> 7649 | J20: =ROUND((H20*50%),0) -> 38245 | K20: 1500 | M20: =ROUND((H20*12.5%),0) -> 9561 | P20: 4300 | Q20: 0 | R20: =SUM(H20:Q20) -> 137745 | S20: =ROUND((H20*10%),0) -> 7649 | T20: 0 | U20: =ROUND((H20*1%),0) -> 765 | AB20: 0 | AD20: 100 | AE20: 10 | AG20: =SUM(S20:AF20) -> 8524 | AH20: =R20-AG20 -> 129221
B21: 11 | C21: 100103 | D21: W.‡gvt gvmyg Aa¨vcK I wefvMxq cÖavb ‡¯‹jt 56500-74400/- wefvMt †U·UvBj BwÄ: g¨v‡bR‡g›U | E21: W.‡gvt gvmyg | F21: Aa¨vcK | G21: 0124100088406 | H21: 76490 | I21: =ROUND((H21*10%),0) -> 7649 | J21: =ROUND((H21*50%),0) -> 38245 | K21: 1500 | M21: =ROUND((H21*12.5%),0) -> 9561 | P21: 4300 | Q21: 1000 | R21: =SUM(H21:Q21) -> 138745 | S21: =ROUND((H21*10%),0) -> 7649 | U21: =ROUND((H21*1%),0) -> 765 | AB21: 250 | AC21: 2189 | AD21: 100 | AE21: 10 | AG21: =SUM(S21:AF21) -> 10963 | AH21: =R21-AG21 -> 127782
B22: 12 | C22: 100023 | D22: W.†gvt Avnmvb nvexe Aa¨vcK I WxbGes cwi: AvBwKDGwmGes( cÖ‡fv÷ AvwRR nj) ‡¯‹jt 56500-74400/- wefvMt †U·UvBj BwÄ: g¨v‡bR‡g›U | E22: W.†gvt Avnmvb nvexe | F22: Aa¨vcK | G22: 0124100085742 | H22: 68770 | I22: =ROUND((H22*10%),0) -> 6877 | J22: =ROUND((H22*50%),0) -> 34385 | K22: 1500 | L22: 600 | M22: =ROUND((H22*12.5%),0) -> 8596 | P22: 4300 | Q22: 1000 | R22: =SUM(H22:Q22) -> 126028 | S22: =ROUND((H22*10%),0) -> 6877 | T22: 21300 | U22: =ROUND((H22*1%),0) -> 688 | AC22: 1879 | AD22: 100 | AE22: 10 | AG22: =SUM(S22:AF22) -> 30854 | AH22: =R22-AG22 -> 95174 | AI22: wRwc 7/40
B23: 13 | C23: 100106 | D23: W.†gvt mvwgDj Bmjvg †PŠayix Aa¨vcK Ges Wxb ‡¯‹jt 56500-74400/- wefvMt imvqb | E23: W.†gvt mvwgDj Bmjvg †PŠayix | F23: Aa¨vcK | G23: 0124100092373 | H23: 68770 | I23: =ROUND((H23*10%),0) -> 6877 | K23: 1500 | L23: =600/30*4 -> 80 | M23: =ROUND((H23*12.5%/30*4),0) -> 1146 | P23: 4300 | R23: =SUM(H23:Q23) -> 82673 | S23: =ROUND((H23*10%),0) -> 6877 | U23: =ROUND((H23*1%),0) -> 688 | X23: 1080 | Y23: 120 | Z23: 30 | AA23: 1694 | AC23: 1879 | AD23: 100 | AE23: 10 | AG23: =SUM(S23:AF23) -> 12478 | AH23: =R23-AG23 -> 70195 | AJ23: AvMvgx gv‡m `vwqZ¡ fvZv Wxb fvZv wWwjU n‡e |
B24: 14 | C24: 100079 | D24: W.KvwbR dvinvbv Aa¨vcK I wefvMxq cÖavY ‡¯‹jt 56500-74400/- | E24: W.KvwbR dvinvbv | F24: Aa¨vcK | G24: 0124100058589 | H24: 68770 | I24: =ROUND((H24*10%),0) -> 6877 | J24: =ROUND((H24*50%),0) -> 34385 | K24: 1500 | M24: =ROUND((H24*12.5%),0) -> 8596 | P24: 4300 | Q24: 1000 | R24: =SUM(H24:Q24) -> 125428 | S24: =ROUND((H24*10%),0) -> 6877 | T24: 14500 | U24: =ROUND((H24*1%),0) -> 688 | AA24: 0 | AB24: 250 | AC24: 640 | AD24: 100 | AE24: 10 | AG24: =SUM(S24:AF24) -> 23065 | AH24: =R24-AG24 -> 102363 | AI24: wRwc 22/48
B25: 15 | C25: 100012 | D25: wkíx Av³vi Aa¨vcK I cwi: (ewniv½b) Ges Wxb ‡¯‹jt 56500-74400/- wefvMt ‡dweªK BwÄwbqvwis | E25: wkwí Av³vi | F25: Aa¨vcK | G25: 0124100085156 | H25: 68770 | I25: =ROUND((H25*10%),0) -> 6877 | J25: =ROUND((H25*50%),0) -> 34385 | K25: 1500 | L25: 600 | M25: =ROUND((H25*12.5%),0) -> 8596 | P25: 4300 | Q25: 500 | R25: =SUM(H25:Q25) -> 125528 | S25: =ROUND((H25*10%),0) -> 6877 | U25: =ROUND((H25*1%),0) -> 688 | Y25: 0 | Z25: 0 | AA25: 0 | AC25: 389 | AD25: 100 | AE25: 10 | AG25: =SUM(S25:AF25) -> 8064 | AH25: =R25-AG25 -> 117464
B26: 16 | C26: 100022 | D26: W. nvwmbv AvLZvi Aa¨vcK Ges Wxb †¯‹jt 56500-74400/ | E26: W. nvwmbv AvLZvi | F26: Aa¨vcK | G26: 0124100096531 | H26: 66120 | I26: =ROUND((H26*10%),0) -> 6612 | J26: 0 | K26: 1500 | L26: =600/30*26 -> 520 | M26: =ROUND((H26*12.5%),0) -> 8265 | P26: 4300 | Q26: 1000 | R26: =SUM(H26:Q26) -> 88317 | S26: =ROUND((H26*10%),0) -> 6612 | U26: =ROUND((H26*1%),0) -> 661 | X26: 1080 | Y26: 120 | Z26: 30 | AA26: 6886 | AD26: 100 | AE26: 10 | AG26: =SUM(S26:AF26) -> 15499 | AH26: =R26-AG26 -> 72818 | AJ26: AvMvgx gv‡m Wxb fvZv c~Y© n‡e |
B27: 17 | C27: 100039 | D27: W. ‡gvt mvB`y¾vgvb Aa¨vcK ‡¯‹jt 56500-74400/ | E27: W. ‡gvt mvB`y¾vgvb | F27: Aa¨vcK | G27: 0124100095431 | H27: 66120 | I27: =ROUND((H27*10%),0) -> 6612 | J27: 0 | K27: 1500 | L27: 0 | P27: 4300 | Q27: 500 | R27: =SUM(H27:Q27) -> 79032 | S27: =ROUND((H27*10%),0) -> 6612 | T27: 0 | U27: =ROUND((H27*1%),0) -> 661 | X27: 1080 | Y27: 80 | Z27: 30 | AA27: 3202 | AB27: 0 | AC27: 1265 | AD27: 100 | AE27: 10 | AG27: =SUM(S27:AF27) -> 13040 | AH27: =R27-AG27 -> 65992
B28: 18 | C28: 100020 | D28: W. KvImvi cvifxb ‡PŠayix Aa¨vcK ‡¯‹jt 56500-74400/- | E28: KvImvi cvifxb †Pxayix | F28: Aa¨vcK | G28: 0124100049422 | H28: 74400 | I28: =ROUND((H28*10%),0) -> 7440 | J28: =ROUND((H28*50%),0) -> 37200 | K28: 1500 | P28: 4300 | Q28: 0 | R28: =SUM(H28:Q28) -> 124840 | S28: =ROUND((H28*10%),0) -> 7440 | T28: 0 | U28: =ROUND((H28*1%),0) -> 744 | X28: 0 | Y28: 0 | Z28: 0 | AA28: 0 | AC28: 1527 | AD28: 100 | AE28: 10 | AG28: =SUM(S28:AF28) -> 9821 | AH28: =R28-AG28 -> 115019
B29: 19 | C29: 100015 | D29: W. iv‡k`v †eMg w`bv Aa¨vcK I †iwR÷ªvi (AwZ: `vwqZ¡) I Wxb ‡¯‹jt 56500-74400/- | E29: iv‡k`v †eMg w`bv | F29: Aa¨vcK | G29: 0124100085035 | H29: 74400 | I29: =ROUND((H29*10%),0) -> 7440 | J29: =ROUND((H29*50%),0) -> 37200 | K29: 1500 | L29: 600 | M29: =ROUND((H29*12.5%),0) -> 9300 | P29: 4300 | Q29: 1000 | R29: =SUM(H29:Q29) -> 135740 | S29: =ROUND((H29*10%),0) -> 7440 | T29: 25000 | U29: =ROUND((H29*1%),0) -> 744 | AB29: 800 | AC29: 1527 | AD29: 100 | AE29: 10 | AG29: =SUM(S29:AF29) -> 35621 | AH29: =R29-AG29 -> 100119 | AI29: wRwc 7/48
B30: 20 | C30: 100026 | D30: W.‡gvt wiqvRyj Bmjvg Aa¨vcK Ges K‡jR cwik©K ‡¯‹j t 56500-74400/- | E30: W.†gvt wiqvRyj Bmjvg | F30: Aa¨vcK | G30: 0124100085762 | H30: 74400 | I30: =ROUND((H30*10%),0) -> 7440 | J30: =ROUND((H30*50%),0) -> 37200 | K30: 1500 | L30: 0 | P30: 4300 | Q30: 1000 | R30: =SUM(H30:Q30) -> 125840 | S30: =ROUND((H30*10%),0) -> 7440 | T30: 19700 | U30: =ROUND((H30*1%),0) -> 744 | X30: 0 | Y30: 0 | Z30: 0 | AA30: 0 | AB30: 250 | AC30: 1845 | AD30: 100 | AE30: 10 | AG30: =SUM(S30:AF30) -> 30089 | AH30: =R30-AG30 -> 95751 | AI30: wRwc 23/40
B31: 21 | C31: 100027 | D31: W.†gvt Bg`v` miKvi Aa¨vcK I we:cÖavY ‡¯‹jt 56500-74400/- | E31: W.†gvt Bg`v` miKvi | F31: Aa¨vcK | G31: 0124100055557 | H31: 74400 | I31: =ROUND((H31*10%),0) -> 7440 | K31: 1500 | L31: 0 | M31: =ROUND((H31*12.5%),0) -> 9300 | P31: 4300 | Q31: 1000 | R31: =SUM(H31:Q31) -> 97940 | S31: =ROUND((H31*10%),0) -> 7440 | T31: 24000 | U31: =ROUND((H31*1%),0) -> 744 | X31: 1080 | Y31: 120 | Z31: 30 | AA31: 492 | AC31: 1845 | AD31: 100 | AE31: 10 | AG31: =SUM(S31:AF31) -> 35861 | AH31: =R31-AG31 -> 62079 | AI31: wRwc 7/36
B32: 22 | C32: 100041 | D32: W.Bgvbv kvnixb Zvwbqv Aa¨vcK I wefvMxq cÖavb wefvMt I‡qU cÖ‡mm BwÄ: ‡¯‹jt 56500-74400/- | E32: W.Bgvbv kvnixb Zvwbqv | F32: Aa¨vcK | G32: 0124100091838 | H32: 66120 | I32: =ROUND((H32*10%),0) -> 6612 | J32: =ROUND((H32*50%),0) -> 33060 | K32: 1500 | L32: 0 | M32: =ROUND((H32*12.5%),0) -> 8265 | P32: 4300 | Q32: 1000 | R32: =SUM(H32:Q32) -> 120857 | S32: =ROUND((H32*10%),0) -> 6612 | T32: 0 | U32: =ROUND((H32*1%),0) -> 661 | X32: 0 | Y32: 0 | Z32: 0 | AB32: 0 | AC32: 640 | AD32: 100 | AE32: 10 | AG32: =SUM(S32:AF32) -> 8023 | AH32: =R32-AG32 -> 112834
B33: 23 | C33: 100035 | D33: W.jvgBqv Rwni Aa¨vcK I Wxb ‡¯‹jt 56500-74400/- | E33: W.jvgBqv Rwni | F33: Aa¨vcK | G33: 0124100091697 | H33: 66120 | I33: =ROUND((H33*10%),0) -> 6612 | J33: =ROUND((H33*50%),0) -> 33060 | K33: 1500 | L33: 600 | M33: =ROUND((H33*12.5%),0) -> 8265 | P33: 4300 | R33: =SUM(H33:Q33) -> 120457 | S33: =ROUND((H33*10%),0) -> 6612 | U33: =ROUND((H33*1%),0) -> 661 | AC33: 640 | AD33: 100 | AE33: 10 | AG33: =SUM(S33:AF33) -> 8023 | AH33: =R33-AG33 -> 112434
B34: 24 | C34: 100037 | D34: W.‡gvt gvneyeyi ingvb Aa¨vcK I wefvMxq cÖavb Ges cÖ±i Ges cÖ‡fv÷(Imgvbx nj) wefvMt d¨vkb GÛ wWRvBb BwÄ: ‡¯‹j t 56500-74400/- | E34: W.‡gvt gvneyeyi ingvb | F34: Aa¨vcK | G34: 0124100067745 | H34: 66120 | I34: =ROUND((H34*10%),0) -> 6612 | K34: 1500 | L34: 0 | M34: =ROUND((H34*12.5%),0) -> 8265 | P34: 4300 | Q34: 500 | R34: =SUM(H34:Q34) -> 87297 | S34: =ROUND((H34*10%),0) -> 6612 | T34: 0 | U34: =ROUND((H34*1%),0) -> 661 | X34: 1080 | Y34: 80 | Z34: 20 | AA34: 117 | AB34: 0 | AC34: 1265 | AD34: 100 | AE34: 10 | AG34: =SUM(S34:AF34) -> 9945 | AH34: =R34-AG34 -> 77352
B35: 25 | C35: 100033 | D35: W. †kL gvgyb Kwei Aa¨vcK (I‡qU cÖ‡m:BwÄ:) I wefvMxq cÖavb Ges cwi:(c I D) ‡¯‹jt 56500-74400/- | E35: W. †kL gvgyb Kwei | F35: Aa¨vcK | G35: 0124100085782 | H35: 66120 | I35: =ROUND((H35*10%),0) -> 6612 | J35: =ROUND((H35*50%),0) -> 33060 | K35: 1500 | L35: 0 | M35: =ROUND((H35*12.5%),0) -> 8265 | P35: 4300 | R35: =SUM(H35:Q35) -> 119857 | S35: =ROUND((H35*10%),0) -> 6612 | U35: =ROUND((H35*1%),0) -> 661 | X35: 0 | Z35: 0 | AC35: 1549 | AD35: 100 | AE35: 10 | AG35: =SUM(S35:AF35) -> 8932 | AH35: =R35-AG35 -> 110925
B36: 26 | C36: 100013 | D36: W.†gvt Rvwn`yj Bmjvg Aa¨vcK I wefvMxq cÖavb ‡¯‹jt 56500-74400/- | E36: W.†gvt Rvwn`yj Bmjvg | F36: mn‡hvMx Aa¨vcK | G36: 0124100053016 | H36: 74400 | I36: =ROUND((H36*10%),0) -> 7440 | K36: 1500 | M36: =ROUND((H36*12.5%),0) -> 9300 | P36: 4300 | R36: =SUM(H36:Q36) -> 96940 | S36: =ROUND((H36*10%),0) -> 7440 | U36: =ROUND((H36*1%),0) -> 744 | X36: 1080 | Y36: 120 | Z36: 80 | AC36: 2152 | AD36: 100 | AE36: 10 | AG36: =SUM(S36:AF36) -> 11726 | AH36: =R36-AG36 -> 85214
B37: 27 | C37: 100031 | D37: W. Zby Av‡idxb Aa¨vcK I wefvMxq cÖavY ‡¯‹jt 56500-74400/- | E37: W. Zby Av‡idxb | F37: mn‡hvMx Aa¨vcK | G37: 0124100089648 | H37: 68770 | I37: =ROUND((H37*10%),0) -> 6877 | J37: 0 | K37: 1500 | L37: 0 | M37: =ROUND((H37*12.5%/30*26),0) -> 7450 | P37: 4300 | Q37: 1000 | R37: =SUM(H37:Q37) -> 89897 | S37: =ROUND((H37*10%),0) -> 6877 | T37: 0 | U37: =ROUND((H37*1%),0) -> 688 | X37: 1080 | Y37: 80 | Z37: 30 | AA37: 5410 | AC37: 924 | AD37: 100 | AE37: 10 | AG37: =SUM(S37:AF37) -> 15199 | AH37: =R37-AG37 -> 74698 | AJ37: `vwqZ¡fvZv AvMvgxgv‡m c~Y© n‡e |
B38: 28 | C38: 100043 | D38: W.G.wU.Gg. d‡qR Avn‡g` Aa¨vcK †¯‹jt 56500-74400/- | E38: W.G.wU.Gg. d‡qR Avn‡g` | F38: mn‡hvMx Aa¨vcK | G38: 0124801012177 | H38: 66120 | I38: =ROUND((H38*10%),0) -> 6612 | K38: 1500 | L38: 0 | P38: =4300+4300 -> 8600 | Q38: 500 | R38: =SUM(H38:Q38) -> 83332 | S38: =ROUND((H38*10%),0) -> 6612 | T38: 11000 | U38: =ROUND((H38*1%),0) -> 661 | X38: 1080 | Y38: 80 | Z38: 20 | AA38: 2192 | AB38: 0 | AC38: 1265 | AD38: 100 | AE38: 10 | AG38: =SUM(S38:AF38) -> 23020 | AH38: =R38-AG38 -> 60312 | AI38: wRwc 18/48 | AJ38: AvMvgxgv‡m †Uwi‡dvbfvZv 4300 UvKv wWwjU n‡e |
B39: 29 | C39: 100045 | D39: W.‡gvnv¤§` dinv`yi ingvb Aa¨vcK I wefvMxq cÖavb †¯‹jt 56500-74400/- | E39: W.‡gvnv¤§` dinv`yi ingvb | F39: mn‡hvMx Aa¨vcK | G39: 0124801012254 | H39: 61120 | I39: =ROUND((H39*10%),0) -> 6112 | J39: =ROUND((H39*50%),0) -> 30560 | K39: 1500 | M39: =ROUND((H39*12.5%/30*26),0) -> 6621 | P39: 4300 | Q39: 500 | R39: =SUM(H39:Q39) -> 110713 | S39: =ROUND((H39*10%),0) -> 6112 | U39: =ROUND((H39*1%),0) -> 611 | AB39: 250 | AC39: 417 | AD39: 100 | AE39: 10 | AG39: =SUM(S39:AF39) -> 7500 | AH39: =R39-AG39 -> 103213 | AJ39: `vwqZ¡fvZv AvMvgxgv‡m c~Y© n‡e |
B40: 30 | C40: 100055 | D40: W.†gvt byiæb bex Aa¨vcK I mn: cÖ±i †¯‹jt 56500-74400/- | E40: W.†gvt byiæb bex | F40: mn‡hvMx Aa¨vcK | G40: 0124801012489 | H40: 61120 | I40: =ROUND((H40*10%),0) -> 6112 | J40: =ROUND((H40*50%),0) -> 30560 | K40: 1500 | M40: =ROUND((H40*12.5%),0) -> 7640 | P40: 4300 | R40: =SUM(H40:Q40) -> 111232 | S40: =ROUND((H40*10%),0) -> 6112 | U40: =ROUND((H40*1%),0) -> 611 | AC40: 417 | AD40: 100 | AE40: 10 | AG40: =SUM(S40:AF40) -> 7250 | AH40: =R40-AG40 -> 103982
B41: 31 | C41: 100105 | D41: W.‡gvnv¤§` iwdKzi ikx` Aa¨vcK †¯‹jt 56500-74400/- | E41: W.‡gvnv¤§` iwdKzj ikx` | F41: mn‡hvMx Aa¨vcK | G41: 0124801014524 | H41: 58760 | I41: =ROUND((H41*10%),0) -> 5876 | J41: =ROUND((H41*50%),0) -> 29380 | K41: 1500 | P41: 4300 | Q41: 1000 | R41: =SUM(H41:Q41) -> 100816 | S41: =ROUND((H41*10%),0) -> 5876 | U41: =ROUND((H41*1%),0) -> 588 | AB41: 250 | AC41: 417 | AD41: 100 | AE41: 10 | AG41: =SUM(S41:AF41) -> 7241 | AH41: =R41-AG41 -> 93575
D42: mn‡hvMx Aa¨vcK | I42: =ROUND((H42*10%),0) -> 0 | R42: =SUM(H42:Q42) -> 0 | AG42: =SUM(S42:AF42) -> 0 | AH42: =R42-AG42 -> 0
B43: 32 | C43: 100014 | D43: m,g,dvinvbv BKevj mn‡hvMx Aa¨vcK (BqvY©) I jvB‡eªixqvb (AwZ: `vwqZ¡) ‡¯‹jt 50000-71200/- | E43: m. g. dvinvbv BKevj | F43: mn‡hvMx Aa¨vcK | G43: 0124100084127 | H43: 65820 | I43: =ROUND((H43*10%),0) -> 6582 | J43: =ROUND((H43*50%),0) -> 32910 | K43: 1500 | L43: 0 | P43: 3000 | Q43: 0 | R43: =SUM(H43:Q43) -> 109812 | S43: =ROUND((H43*10%),0) -> 6582 | T43: 0 | U43: =ROUND((H43*1%),0) -> 658 | X43: 0 | Y43: 0 | Z43: 0 | AA43: 0 | AB43: 0 | AC43: 1527 | AD43: 100 | AE43: 10 | AG43: =SUM(S43:AF43) -> 8877 | AH43: =R43-AG43 -> 100935
...

Sheet Sheet3
B1: evsjv‡`k †U·UvBj wek¦we`¨vjq
B2: Kg©KZ©v‡`i †eZb-fvZvw`i wej - Ryb 2026|
B4: µt bs | D4: bvg, c`ex I †eZb‡¯‹j | R4: KZ©b mg~n | AG4: bxU `vex | AH4: gšÍe¨
H5: g~j‡eZb | I5: we‡kl myweav | J5: evoxfvov fvZv | K5: wPwKrmv fvZv | L5: we‡kl fvZv/`vwqZ¡ fvZv | O5: ‡Uwj/†gvev fvZv | P5: wk¶v fvZv | Q5: †gvU †eZb | R5: wRwc dvÛ Puv`v | T5: Kj¨vY Znwej | U5: ‡hŠ_ exgv | V5: evoxfvov | W5: M¨vmwej | X5: cvwb I cqtKi | Y5: ‡cŠi Ki | Z5: we`y¨r wej | AA5: Mvox fvov | AB5: AvqKi | AC5: Kg©KZ©v mwgwZi Puv`v | AD5: ivR¯^ ÷¨v¤ú | AE5: AwWU AvcwËK…Z A_© Av`vq/ewaZ© †eZb KZ©b/ †W †Kqvi | AF5: ‡gvU KZ©b
C6: †KvW bs | E6: bvg | F6: c`ex | G6: wnmve bs | R6: Puv`v | S6: AwMÖg cÖZ¨vnvi
B7: 1 | C7: 200002 | D7: gynv¤§` Kvgiæ¾vgvb †PŠayix Dc-cwiPvjK (A_© I wnmve) ‡¯‹jt 50000-71200/- | E7: gynv¤§` Kvgiæ¾vgvb †PŠayix | F7: Dc-cwiPvjK (A_© I wnmve) | G7: 0124100087114 | H7: 71200 | I7: 7120 | J7: 35600 | K7: 1500 | L7: 0 | O7: 3000 | P7: 1000 | Q7: 119420 | R7: 7120 | T7: 712 | W7: 0 | X7: 0 | Y7: 0 | AA7: 250 | AC7: 50 | AD7: 10 | AF7: 8142 | AG7: 111278
B8: 2 | C8: 200003 | D8: †gvt †iRvDj nK cix¶v wbqš¿K (P:`v) ‡¯‹jt 50000-71200/- | E8: †gvt †iRvDj nK | F8: cix¶v wbqš¿K (P:`v) | G8: 0124100086666 | H8: 71200 | I8: 7120 | J8: 35600 | K8: 1500 | L8: 1500 | O8: 3000 | P8: 1000 | Q8: 120920 | R8: 7120 | T8: 712 | W8: 0 | X8: 0 | Y8: 0 | AA8: 250 | AB8: 3512 | AC8: 50 | AD8: 10 | AF8: 11654 | AG8: 109266
B9: 3 | C9: 200005 | D9: ‡gvt gwbiæ¾vgvb Dc- cwiPvjK (AwWU) ‡¯‹jt 43000-69850/- | E9: †gvt gwbiæ¾vgvb | F9: Dc-cwiPvjK (AwWU ) | G9: 0124100086186 | H9: 63960 | I9: 6396 | J9: 31980 | K9: 1500 | Q9: 103836 | R9: 6396 | T9: 640 | AA9: 250 | AB9: 500 | AC9: 50 | AD9: 10 | AF9: 7846 | AG9: 95990 | AH9: &
B10: 4 | C10: 200006 | D10: gynv¤§` kixdzi ingvb ‡WcywU †iwRóªviGBP Avi(AwZ: `vwqZ¡ GKv‡WwgK) ‡¯‹jt 43000-69850/- | E10: gynv¤§` kixdzi ingvb | F10: ‡WcywU †iwR÷ªvi | G10: 0124100086616 | H10: 63960 | I10: 6396 | K10: 1500 | L10: 1500 | P10: 500 | Q10: 73856 | R10: 6396 | T10: 640 | W10: 1080 | X10: 120 | Y10: 30 | Z10: 1936 | AB10: 1853 | AC10: 50 | AD10: 10 | AF10: 12115 | AG10: 61741
B11: 5 | C11: 200007 | D11: ‡gvt †gveviK †nv‡mb Dc- cix¶v wbqš¿K ‡¯‹jt 43000-69850/- | E11: ‡gvt †gveviK †nv‡mb | F11: Dc- cix¶v wbqš¿K | G11: 0124801012014 | H11: 53610 | I11: 5361 | J11: 26805 | K11: 1500 | L11: 0 | P11: 500 | Q11: 87776 | R11: 5361 | T11: 536 | W11: 0 | X11: 0 | Y11: 0 | Z11: 0 | AA11: 250 | AB11: 663 | AC11: 50 | AD11: 10 | AF11: 6870 | AG11: 80906
B12: 6 | C12: 200012 | D12: ¯^cb Kzgvi gÛj Dc- cwiPvjK(wdwRt GWyt) ‡¯‹jt 43000-69850/- | E12: ¯^cb Kzgvi gÛj | F12: Dc- cwiPvjK(wdwRt GWyt) | G12: 0124100087841 | H12: 46970 | I12: 4697 | J12: 0 | K12: 1500 | O12: 0 | P12: 1000 | Q12: 54167 | R12: 4697 | S12: 0 | T12: 470 | W12: 1080 | X12: 120 | Y12: 30 | Z12: 1881 | AA12: 0 | AB12: 417 | AC12: 50 | AD12: 10 | AF12: 8755 | AG12: 45412
B13: 7 | C13: 200057 | D13: D‡¤§ gnwmbv AvwQqv †eMg Dc- cwiPvjK †¯‹jt 43000-69850/- | E13: D‡¤§ gnwmbv AvwQqv †eMg | F13: Dc- cwiPvjK | G13: 0124801014643 | H13: 46970 | I13: 4697 | J13: 23485 | K13: 1500 | P13: 500 | Q13: 77152 | R13: 4697 | T13: 470 | AA13: 250 | AB13: 417 | AC13: 50 | AD13: 10 | AF13: 5894 | AG13: 71258
B14: 8 | C14: 200009 | D14: kviwgb Av³vi Dc- cwiPvjK(m¨vjvix) ‡¯‹jt 43000-69850/- | E14: kviwgb Av³vi | F14: Dc- cwiPvjK(m¨vjvix) | G14: 0124801012979 | H14: 53610 | I14: 5361 | J14: 26805 | K14: 1500 | L14: 0 | P14: 0 | Q14: 87276 | R14: 5361 | T14: 536 | W14: 0 | X14: 0 | Y14: 0 | Z14: 0 | AB14: 417 | AC14: 50 | AD14: 10 | AF14: 6374 | AG14: 80902
B15: 9 | C15: 200017 | D15: gviRvbx Zzeb bvnvi Dc- cix¶v wbqš¿K ‡¯‹j t 43000-69850/- | E15: gviRvbx Zzeb bvnvi | F15: Dc- cix¶v wbqš¿K | G15: 0124100087767 | H15: 44940 | I15: 4494 | J15: 0 | K15: 1500 | L15: 0 | O15: 0 | P15: 1000 | Q15: 51934 | R15: 4494 | S15: 0 | T15: 449 | W15: 1080 | X15: 30 | Y15: 10 | Z15: 2579 | AA15: 0 | AB15: 417 | AC15: 50 | AD15: 10 | AF15: 9119 | AG15: 42815
B16: 10 | C16: 200018 | D16: †gvt Avwmdzi ingvb †cÖvMÖvgvi †¯‹j t 35500-67010/- | E16: ‡gvt Avwmdzi ingvb | F16: †cÖvMÖvgvi | G16: 0124801013618 | H16: 43170 | I16: 4317 | J16: 21585 | K16: 1500 | P16: 500 | Q16: 71072 | R16: 4317 | S16: 5000 | T16: 432 | AB16: 417 | AC16: 50 | AD16: 10 | AF16: 10226 | AG16: 60846 | AH16: wRwc 34/48
B17: 11 | C17: 200056 | D17: ‡kL †gvt gvkiƒi hvqxg wmwbqi mn: cÖ‡KŠkjx (wmwfj) †¯‹jt 35500-67010/- | E17: ‡kL †gvt gvkiƒg hvqxg | F17: wmwbqi mn: cÖ‡KŠkjx (wmwfj) | G17: 0124801013968 | H17: 41110 | I17: 4111 | J17: 20555 | K17: 1500 | Q17: 67276 | R17: 4111 | T17: 411 | AB17: 417 | AC17: 50 | AD17: 10 | AF17: 4999 | AG17: 62277
B18: 12 | C18: 200073 | D18: ‡gvt AvdRvj †nv‡mb wbevnx© cÖ‡KŠkjx 35500-67010/- | E18: ‡gvt AvdRvj †nv‡mb | F18: wbevnx© cÖ‡KŠkjx | G18: 0124801019930 | H18: 39150 | I18: 3915 | J18: 19575 | K18: 1500 | P18: 1000 | Q18: 65140 | R18: 3915 | T18: 392 | AA18: 250 | AB18: 417 | AC18: 50 | AD18: 10 | AF18: 5034 | AG18: 60106
B19: 13 | C19: 200008 | D19: AjK P›`ª †` mnKvix cwiPvjK(ev‡RU) ‡¯‹jt 29000-63410/- | E19: AjK P›`ª †` | F19: mnKvix cwiPvjK(ev‡RU) | G19: 0124100093112 | H19: 40840 | I19: 4084 | J19: 20420 | K19: 1500 | L19: 0 | O19: 0 | P19: 500 | Q19: 67344 | R19: 4084 | S19: 0 | T19: 408 | W19: 0 | X19: 0 | Y19: 0 | Z19: 0 | AA19: 0 | AB19: 417 | AC19: 50 | AD19: 10 | AF19: 4969 | AG19: 62375
B20: 14 | C20: 200026 | D20: ‡nvmvBb †gvnv¤§` AvKei mnKvix cwiPvjK(cÖwKDi‡g›U) ‡¯‹jt 29000-63410/- | E20: ‡nvmvBb †gvnv¤§` AvKei | F20: mnKvix cwiPvjK(cÖwKDi‡g›U) | G20: 0124100089859 | H20: 40840 | I20: 4084 | J20: 20420 | K20: 1500 | L20: 0 | O20: 0 | P20: 0 | Q20: 66844 | R20: 4084 | S20: 0 | T20: 408 | W20: 0 | X20: 0 | Y20: 0 | AA20: 0 | AB20: 417 | AC20: 50 | AD20: 10 | AF20: 4969 | AG20: 61875
B21: 15 | C21: 200027 | D21: BwZgwb mnKvix ‡iwR÷ªvi (GBP Avi) ‡¯‹jt 29000-63410/- | E21: BwZgwb | F21: mnKvix ‡iwR÷ªvi (GBP Avi) | G21: 0124100093059 | H21: 40840 | I21: 4084 | J21: 20420 | K21: 1500 | L21: 0 | O21: 0 | P21: 1000 | Q21: 67844 | R21: 4084 | S21: 9375 | T21: 408 | AA21: 250 | AB21: 417 | AC21: 50 | AD21: 10 | AF21: 14594 | AG21: 53250 | AH21: wRwc 14/48
B22: 16 | C22: 200010 | D22: †gvt dviæKzj Bmjvg †PŠt wmwbqi †UKwbK¨vj Awdmvi ‡¯‹j 29000-53060/- | E22: †gvt dviæKzj Bmjvg †PŠt | F22: wmwbt †UKwbK¨vj Awdmvi (j¨ve) | G22: 0124100056872 | H22: 45040 | I22: 4504 | J22: 0 | K22: 1500 | L22: 0 | O22: 0 | P22: 1000 | Q22: 52044 | R22: 4504 | T22: 450 | W22: 1080 | X22: 30 | Y22: 10 | Z22: 1214 | AA22: 0 | AB22: 417 | AC22: 50 | AD22: 10 | AF22: 7765 | AG22: 44279
B23: 17 | C23: 200015 | D23: ‡nv‡mb knx` miIqv`©x ©wmwbqi †UKwbK¨vj Awdmvi ‡¯‹j : 29000-63410/- | E23: ‡nv‡mb knx` †mviIqv`x© | F23: wmwbt †UKwbK¨vj Awdmvi (j¨ve) | G23: 0124100089436 | H23: 45040 | I23: 4504 | K23: 1500 | L23: 0 | O23: 0 | P23: 500 | Q23: 51544 | R23: 4504 | S23: 0 | T23: 450 | W23: 1080 | X23: 30 | Y23: 10 | Z23: 1199 | AA23: 0 | AB23: 417 | AC23: 50 | AD23: 10 | AF23: 7750 | AG23: 43794
B24: 18 | C24: 200016 | D24: †gvt RvKvwiqv ingvb wmwbqi †UKwbK¨vj Awdmvi ‡¯‹j: 29000-63410/- | E24: ‡gvt RvKvwiqv ingvb | F24: wmwbt †UKwbK¨vj Awdmvi (j¨ve) | G24: 0124100085096 | H24: 42890 | I24: 4289 | J24: 0 | K24: 1500 | L24: 0 | O24: 0 | P24: 1000 | Q24: 49679 | R24: 4289 | S24: 13550 | T24: 429 | W24: 1080 | X24: 30 | Y24: 10 | Z24: 1554 | AA24: 0 | AB24: 417 | AC24: 50 | AD24: 10 | AF24: 21419 | AG24: 28260 | AH24: wRwc 16/48
B25: 19 | C25: 200069 | D25: RvwKiæj Bmjvg wcUvi mnKvix ‡iwR÷ªvi(GKv‡WwgK) ‡¯‹jt 29000-63410/- | E25: RvwKiæj Bmjvg wcUvi | F25: mnKvix ‡iwR÷ªvi (GKv‡WwgK) | G25: 2611201003232 | H25: 33580 | I25: 3358 | J25: 18469 | K25: 1500 | P25: 500 | Q25: 57407 | R25: 3358 | T25: 336 | AB25: 417 | AC25: 50 | AD25: 10 | AF25: 4171 | AG25: 53236
B26: 20 | C26: 200029 | D26: †gvQvt †di‡`Šmx LvZzb mnKvix ‡iwR÷ªvi (GKv‡WwgK) ‡¯‹jt 29000-63410/- | E26: ‡gvQvt †di‡`Šmx LvZzb | F26: mnKvix ‡iwR÷ªvi (GKv‡WwgK) | G26: 0124100097005 | H26: 35260 | I26: 3526 | J26: 0 | K26: 1500 | L26: 0 | O26: 0 | P26: 0 | Q26: 40286 | R26: 3526 | S26: 10000 | T26: 353 | W26: 1080 | X26: 30 | Y26: 10 | Z26: 647 | AA26: 0 | AB26: 417 | AC26: 50 | AD26: 10 | AF26: 16123 | AG26: 24163 | AH26: wRwc 19/33
B27: 21 | C27: 200011 | D27: †gvt Rvnv½xi ‡nv‡mb wmwbqi †UKwbK¨vj Awdmvi ‡¯‹jt 29000-63410/- | E27: †gvt Rvnv½xi ‡nv‡mb | F27: wmwbqi †UKwbK¨vj Awdmvi | G27: 0124100089385 | H27: 42890 | I27: 4289 | K27: 1500 | Q27: 48679 | R27: 4289 | S27: 13650 | T27: 429 | W27: 1080 | X27: 30 | Y27: 10 | Z27: 564 | AB27: 417 | AC27: 50 | AD27: 10 | AF27: 20529 | AG27: 28150 | AH27: wRwc 3/48
B28: 22 | C28: 200054 | D28: iæKmvbv RvbœvZ bIixb mnKvix cwiPvjK (wi‡cvwUs) ‡¯‹jt 29000-63410/- | E28: iæKmvbv RvbœvZ bIwib | F28: mnKvix cwiPvjK (wi‡cvwUs) | G28: 0124801013965 | H28: 37030 | I28: 3703 | J28: 19500 | K28: 1500 | Q28: 61733 | R28: 3703 | T28: 370 | AB28: 417 | AC28: 50 | AD28: 10 | AF28: 4550 | AG28: 57183
B29: 23 | C29: 200055 | D29: ‡gvt kwdKzj Bmjvg mn: cwi: cvewjK : wi‡jkb †¯‹jt 29000-63410/- | E29: ‡gvt kwdKzj Bmjvg | F29: mn: cwi: cvewjK : wi‡jkb | G29: 0124801014068 | H29: 35260 | I29: 3526 | J29: 19393 | K29: 1500 | P29: 500 | Q29: 60179 | R29: 3526 | S29: 6700 | T29: 353 | AB29: 417 | AC29: 50 | AD29: 10 | AF29: 11056 | AG29: 49123 | AH29: wRwc 1/48
B30: 24 | C30: 200019 | D30: ‡gvt Gnmvbyj Kwig mnKvix †iwR÷ªvi †¯‹jt 29000-63410/- | E30: ‡gvt Gnmvbyj Kwig | F30: mnKvix †iwR÷ªvi | G30: 0124100084066 | H30: 35260 | I30: 3526 | J30: 19393 | K30: 1500 | L30: 3000 | O30: 0 | P30: 1000 | Q30: 63679 | R30: 3526 | T30: 353 | AA30: 0 | AB30: 417 | AC30: 50 | AD30: 10 | AF30: 4356 | AG30: 59323
B31: 25 | C31: 200030 | D31: †gvnv¤§` Avwidzi ingvb mnKvix †iwR÷ªvi †¯‹jt 29000-63410/- wkÿvQzwU :01/02/2026 †_‡K 31/01/2030 | E31: ‡gvt Avwidzi ingvb | F31: mnKvix †iwR÷ªvi | G31: 0124801012484 | H31: 33580 | I31: 3358 | J31: 18469 | K31: 1500 | L31: 0 | O31: 0 | P31: 0 | Q31: 56907 | R31: 3358 | S31: 5000 | T31: 336 | W31: 0 | X31: 0 | Y31: 0 | AA31: 250 | AB31: 417 | AC31: 50 | AD31: 10 | AF31: 9421 | AG31: 47486 | AH31: wRwc 21/48 wkÿvQzwU
B32: 26 | C32: 200031 | D32: ‡gvt wejøvj †nv‡mb mnKvix †iwR÷ªvi †¯‹jt 29000-63410/- | E32: ‡gvt wejøvj †nv‡mb | F32: mnKvix †iwR÷ªvi | G32: 0124801012485 | H32: 33580 | I32: 3358 | K32: 1500 | O32: 0 | P32: 500 | Q32: 38938 | R32: 3358 | S32: 8000 | T32: 336 | W32: 1080 | X32: 30 | Y32: 10 | Z32: 889 | AB32: 417 | AC32: 50 | AD32: 10 | AF32: 14180 | AG32: 24758 | AH32: wRwc 14/40
B33: 27 | C33: 200032 | D33: †gvt dviæK †nvmvBb mnKvix †iwR÷ªvi †¯‹jt 29000-63410/- | E33: ‡gvt dviæK †nvmvBb | F33: mnKvix †iwR÷ªvi | G33: 0124801012486 | H33: 33580 | I33: 3358 | K33: 1500 | L33: 0 | O33: 0 | P33: 500 | Q33: 38938 | R33: 3358 | S33: 0 | T33: 336 | W33: 1080 | X33: 30 | Y33: 10 | Z33: 1350 | AA33: 0 | AB33: 417 | AC33: 50 | AD33: 10 | AF33: 6641 | AG33: 32297
B34: 28 | C34: 200061 | D34: †gvt kvgxg Bmjvg mnKvix cwiPvjK †¯‹jt 29000-63410/- | E34: †gvt kvgxg Bmjvg | F34: mnKvix cwiPvjK | G34: 0124801016234 | H34: 33580 | I34: 3358 | J34: 18469 | K34: 1500 | P34: 500 | Q34: 57407 | R34: 3358 | S34: 5000 | T34: 336 | AB34: 417 | AC34: 50 | AD34: 10 | AF34: 9171 | AG34: 48236 | AH34: wRwc 6/40
B35: 29 | C35: 200013 | D35: cjvk P›`ª bv_ wmwbqi†UKwbK¨vj Awdmvi ‡¯‹jt 29000-63410/- | E35: cjvk P›`ª bv_ | F35: wmwbqi†UKwbK¨vj Awdmvi | G35: 0124100032873 | H35: 45040 | I35: 4504 | J35: 22520 | K35: 1500 | L35: 0 | O35: 0 | P35: 1000 | Q35: 74564 | R35: 4504 | S35: 12500 | T35: 450 | AA35: 0 | AB35: 417 | AC35: 50 | AD35: 10 | AF35: 17931 | AG35: 56633 | AH35: wRwc 15/20
B36: 30 | C36: 200062 | D36: Avãyj gwZb †`Iqvb mnKvix cwiPvjK(wej GÛ dvÛ) †¯‹jt 29000- 63410/- | E36: Avãyj gwZb †`Iqvb | F36: mnKvix cwiPvjK(wej GÛ dvÛ) | G36: 0124801016235 | H36: 31980 | I36: 3198 | J36: 17589 | K36: 1500 | Q36: 54267 | R36: 3198 | T36: 320 | AB36: 417 | AC36: 50 | AD36: 10 | AF36: 3995 | AG36: 50272
B37: 31 | C37: 200079 | D37: AvwZKzi ingvb mnKvix cwiPvjK(cwiKíbv) †¯‹jt 29000- 63410/- ‡hvM`vbt 03/07/2025 | E37: AvwZKzi ingvb | F37: mnKvix cwiPvjK(cwiKíbv) | G37: 0124801020972 | H37: 33580 | I37: 3358 | J37: 18469 | K37: 1500 | Q37: 56907 | R37: 3358 | T37: 336 | AB37: 417 | AC37: 50 | AD37: 10 | AF37: 4171 | AG37: 52736
B38: 32 | C38: 200014 | D38: mviwgb Av³vi wmwbqi †UKwbK¨vj Awdmvi †¯‹jt 29000-63410/- | E38: mviwgb Av³vi | F38: †UKwbK¨vj Awdmvi (j¨ve) | G38: 0124100089899 | H38: 45040 | I38: 4504 | K38: 1500 | L38: 0 | O38: 0 | P38: 500 | Q38: 51544 | R38: 4504 | T38: 450 | W38: 1080 | X38: 30 | Y38: 10 | Z38: 1969 | AA38: 0 | AB38: 417 | AC38: 50 | AD38: 10 | AF38: 8520 | AG38: 43024
B39: 33 | C39: 200020 | D39: ‡gvnv¤§` AvjvDwÏb wmwbqi †UKwbK¨vj Awdmvi †¯‹jt 29000-63410/- | E39: ‡gvt AvjvDwÏb | F39: †UKwbK¨vj Awdmvi | G39: 0124100089688 | H39: 33580 | I39: 3358 | J39: 0 | K39: 1500 | L39: 0 | O39: 0 | P39: 1000 | Q39: 39438 | R39: 3358 | S39: 11000 | T39: 336 | W39: 1080 | X39: 30 | Y39: 10 | Z39: 942 | AA39: 0 | AB39: 417 | AC39: 50 | AD39: 10 | AF39: 17233 | AG39: 22205 | AH39: wRwc 10/48
B40: 34 | C40: 200021 | D40: gxi ‡gvt Avwgbyj BKivg †UKwbK¨vj Awdmvi ‡¯‹j 29000-63410/- | E40: gxi ‡gvt Avwgbyj BKivg | F40: †UKwbK¨vj Awdmvi | G40: 0124100069865 | H40: 57510 | I40: 5751 | K40: 1500 | O40: 0 | P40: 1000 | Q40: 65761 | R40: 5751 | T40: 575 | W40: 1080 | X40: 30 | Y40: 10 | Z40: 4080 | AB40: 1013 | AC40: 50 | AD40: 10 | AF40: 12599 | AG40: 53162
B41: 35 | C41: 200024 | D41: ‡gvnv¤§` †Zvdv‡qj †nv‡mb Lvb †UKwbK¨vj Awdmvi ‡¯‹j t 22000-53060/- | E41: ‡gvt †Zvdv‡qj †nv‡mb Lvb | F41: †UKwbK¨vj Awdmvi | G41: 0124100089739 | H41: 30990 | I41: 3099 | J41: 0 | K41: 1500 | L41: 0 | O41: 0 | P41: 1000 | Q41: 36589 | R41: 3099 | S41: 0 | T41: 310 | W41: 1080 | X41: 30 | Y41: 10 | Z41: 2184 | AA41: 0 | AB41: 417 | AC41: 50 | AD41: 10 | AF41: 7190 | AG41: 29399
...

Sheet Sheet4
B1: evsjv‡`k †U·UvBj wek¦we`¨vjq
B2: ‡ZRMuvI, XvKv-1208|
B3: Kg©Pvix‡`i ‡eZb fvZvw`i wej Ryb - 2026 |
B5: µt bs | D5: bvg , c`ex I †eZb‡¯‹j | H5: cÖvwßmg~n | R5: KZ©bmg~n | AG5: bxU | AH5: gšÍe¨ | AI5: ¯^v¶i
H6: g~j‡eZb | I6: we‡kl myweav | J6: evoxfvov fvZv | K6: wPwKrmv fvZv | L6: hvZvqvZ fvZv | M6: wUwdb fvZv | N6: wk¶v fvZv | O6: ‡avjvB fvZv | P6: we‡kl fvZv | Q6: ‡gvU | R6: mvaviY fwel¨ Znwej | T6: Kj¨vY | U6: ‡hŠ_ exgv | V6: evoxfvov | W6: M¨vm | X6: cvwb I cqt | Y6: †cŠi Ki | Z6: we`y¨r | AA6: Mvox fvov | AB6: AvqKi | AC6: mwgwZi Puv`v | AD6: ivR¯^ ÷¨v¤ú | AE6: 1 w`‡bi †eZb KZ©b /ewa©Z †eZb KZ©b | AF6: ‡gvU KZ©b
C7: ‡KvW bs | R7: Puv`v | S7: cÖZ¨vnvi
B8: 1 | C8: 300123 | D8: ‡gvt †iRvDj Kwig d‡UvMÖvdvi †¯‹j t 12500-30230/- | E8: ‡gvt †iRvDj Kwig | F8: d‡UvMÖvdvi | G8: 0124801015746 | H8: 30230 | I8: =ROUND((H8*15%),0) -> 4535 | J8: =ROUND((H8*55%),0) -> 16627 | K8: 1500 | L8: 300 | M8: 200 | N8: 500 | Q8: =SUM(H8:O8) -> 53892 | R8: =ROUND((H8*10%),0) -> 3023 | S8: 3450 | T8: =ROUND((H8*1%),0) -> 302 | AB8: 417 | AC8: 20 | AD8: 10 | AF8: =SUM(R8:AE8) -> 7222 | AG8: =Q8-AF8 -> 46670 | AH8: wRwc 23/48 | AI8: 2wU Bbwµ‡g›U eÜ _vK‡e | 2024,2025
B9: 2 | C9: 300018 | D9: ¯^‡`k P›`ª ivq Kv‡c©›Uvi †MÖW-1 ‡¯‹jt 12500-30230/- | E9: ¯^‡`k P›`ª ivq | F9: Kv‡c©›Uvi †MÖW-1 | G9: 0124100089779 | H9: 22530 | I9: =ROUND((H9*15%),0) -> 3380 | K9: 1500 | L9: 300 | M9: 200 | N9: 500 | O9: 0 | Q9: =SUM(H9:O9) -> 28410 | R9: =ROUND((H9*10%),0) -> 2253 | S9: 5000 | T9: =ROUND((H9*1%),0) -> 225 | V9: 0 | W9: 1080 | X9: 30 | Y9: 10 | Z9: 1785 | AA9: 0 | AC9: 20 | AD9: 10 | AF9: =SUM(R9:AE9) -> 10413 | AG9: =Q9-AF9 -> 17997 | AH9: wRwc 11/20
B10: 3 | C10: 300137 | D10: ‡gvt AvwZKzj Bmjvg ‡gwWK¨vj mnKvix ‡¯‹jt 12500-30230/- | E10: ‡gvt AvwZKzj Bmjvg | F10: ‡gwWK¨vj mnKvix | G10: 0124801020072 | H10: 13130 | I10: =ROUND((H10*15%),0) -> 1970 | K10: 1500 | L10: 300 | M10: 200 | Q10: =SUM(H10:O10) -> 17100 | R10: =ROUND((H10*10%),0) -> 1313 | T10: =ROUND((H10*1%),0) -> 131 | W10: 1080 | X10: 30 | Y10: 10 | Z10: 1237 | AC10: 20 | AD10: 10 | AF10: =SUM(R10:AE10) -> 3831 | AG10: =Q10-AF10 -> 13269
B11: 4 | D11: iwn` nvmvb ivRy Kw¤úDUvi Acv‡iUi ‡¯‹jt 12500-30230/- ‡hvM`vb : 03/02/206 | E11: iwn` nvmvb ivRy | F11: Kw¤úDUvi Acv‡iUi | G11: 0124801021365 | H11: 12500 | I11: =ROUND((H11*15%),0) -> 1875 | J11: =ROUND((H11*60%),0) -> 7500 | K11: 1500 | L11: 300 | M11: 200 | Q11: =SUM(H11:O11) -> 23875 | R11: =ROUND((H11*10%),0) -> 1250 | T11: =ROUND((H11*1%),0) -> 125 | AC11: 20 | AD11: 10 | AF11: =SUM(R11:AE11) -> 1405 | AG11: =Q11-AF11 -> 22470
B12: 5 | D12: bvCg Kw¤úDUvi Acv‡iUi ‡¯‹jt 12500-30230/- ‡hvM`vb : 13/04/206 | E12: bvCg | F12: Kw¤úDUvi Acv‡iUi | G12: 4435401017490 | H12: 12500 | I12: =ROUND((H12*15%),0) -> 1875 | J12: =ROUND((H12*60%),0) -> 7500 | K12: 1500 | L12: 300 | M12: 200 | Q12: =SUM(H12:O12) -> 23875 | R12: =ROUND((H12*10%),0) -> 1250 | T12: =ROUND((H12*1%),0) -> 125 | AD12: 10 | AF12: =SUM(R12:AE12) -> 1385 | AG12: =Q12-AF12 -> 22490
B13: 6 | C13: 300004 | D13: ‡gvt ev‡qwR` †nvmvBb Awdm mnt Kvg Kw¤út Acv †¯‹jt 11000-26590/- | E13: ‡gvt ev‡qwR` †nvmvBb | F13: Awdm mnt Kvg Kw¤út Acvt | G13: 0124801012680 | H13: 15500 | I13: =ROUND((H13*15%),0) -> 2325 | J13: =ROUND((H13*60%),0) -> 9300 | K13: 1500 | L13: 300 | M13: 200 | N13: 500 | O13: 0 | Q13: =SUM(H13:O13) -> 29625 | R13: =ROUND((H13*10%),0) -> 1550 | S13: 2950 | T13: =ROUND((H13*1%),0) -> 155 | AA13: 0 | AC13: 20 | AD13: 10 | AF13: =SUM(R13:AE13) -> 4685 | AG13: =Q13-AF13 -> 24940 | AH13: wRwc 18/48
B14: 7 | C14: 300140 | D14: ‡gvt †mv‡nj ivbv Awdm mnt Kvgt Kw¤útAcvt ‡¯‹j t 11000-26590/- ‡hvM`vb t 13/02/2024 | E14: ‡gvt †mv‡nj ivbv | F14: Awdm mnt Kvgt Kw¤útAcvt | G14: 0124801018391 | H14: 11550 | I14: =ROUND((H14*15%),0) -> 1733 | J14: =ROUND((H14*60%),0) -> 6930 | K14: 1500 | L14: 300 | M14: 200 | Q14: =SUM(H14:O14) -> 22213 | R14: =ROUND((H14*10%),0) -> 1155 | T14: =ROUND((H14*1%),0) -> 116 | AC14: 20 | AD14: 10 | AF14: =SUM(R14:AE14) -> 1301 | AG14: =Q14-AF14 -> 20912
B15: 8 | C15: 300139 | D15: AvwZKzi ingvb dqmvj Awdm mnt Kvgt Kw¤útAcvt ‡¯‹j t 11000-26590/-†hvM`vb t 13/02/2024 | E15: AvwZKzi ingvb dqmvj | F15: Awdm mnt Kvgt Kw¤útAcvt | G15: 0124801020144 | H15: 11550 | I15: =ROUND((H15*15%),0) -> 1733 | J15: =ROUND((H15*60%),0) -> 6930 | K15: 1500 | L15: 300 | M15: 200 | Q15: =SUM(H15:O15) -> 22213 | R15: =ROUND((H15*10%),0) -> 1155 | T15: =ROUND((H15*1%),0) -> 116 | AC15: 20 | AD15: 10 | AF15: =SUM(R15:AE15) -> 1301 | AG15: =Q15-AF15 -> 20912
B16: 9 | C16: 300138 | D16: wicb P›`ª miKvi Awdm mnt Kvgt Kw¤útAcvt ‡¯‹j t 11000-26590/- †hvM`vb t 13/02/2024 | E16: wicb P›`ª miKvi | F16: Awdm mnt Kvgt Kw¤útAcvt | G16: 2116201052345 | H16: 11550 | I16: =ROUND((H16*15%),0) -> 1733 | J16: =ROUND((H16*60%),0) -> 6930 | K16: 1500 | L16: 300 | M16: 200 | Q16: =SUM(H16:O16) -> 22213 | R16: =ROUND((H16*10%),0) -> 1155 | T16: =ROUND((H16*1%),0) -> 116 | AC16: 20 | AD16: 10 | AF16: =SUM(R16:AE16) -> 1301 | AG16: =Q16-AF16 -> 20912
B17: 10 | C17: 300037 | D17: †gvt †`‡jvqvi †nv‡mb µvdU BÝUªv±i ‡¯‹jt 11000-26590/- | E17: †gvt †`‡jvqvi †nv‡mb | F17: µvdU BÝUªv±i | G17: 0124100020553 | H17: 20810 | I17: =ROUND((H17*15%),0) -> 3122 | J17: 0 | K17: 1500 | L17: 300 | M17: 200 | Q17: =SUM(H17:O17) -> 25932 | R17: =ROUND((H17*10%),0) -> 2081 | T17: =ROUND((H17*1%),0) -> 208 | V17: 0 | W17: 1080 | X17: 30 | Y17: 10 | Z17: 1206 | AA17: 0 | AC17: 20 | AD17: 10 | AF17: =SUM(R17:AE17) -> 4645 | AG17: =Q17-AF17 -> 21287
B18: 11 | C18: 300039 | D18: ‡gvt nvwbd nvIjv`vi µvdU BÝUªv±i ‡¯‹jt 11000-26590/- | E18: ‡gvt nvwbd nvIjv`vi | F18: µvdU BÝUªv±i | G18: 0124100062041 | H18: 18860 | I18: =ROUND((H18*15%),0) -> 2829 | J18: 0 | K18: 1500 | L18: 300 | M18: 200 | N18: 500 | Q18: =SUM(H18:O18) -> 24189 | R18: =ROUND((H18*10%),0) -> 1886 | T18: =ROUND((H18*1%),0) -> 189 | V18: 0 | W18: 1080 | X18: 30 | Y18: 10 | Z18: 1267 | AA18: 0 | AC18: 20 | AD18: 10 | AF18: =SUM(R18:AE18) -> 4492 | AG18: =Q18-AF18 -> 19697
B19: 12 | C19: 300041 | D19: ‡gvt †nv‡mb †`Iqvb µvdU BÝUªv±i ‡¯‹jt 11000-26590/- | E19: ‡gvt †nv‡mb †`Iqvb | F19: µvdU BÝUªv±i | G19: 0124100089708 | H19: 18860 | I19: =ROUND((H19*15%),0) -> 2829 | J19: =ROUND((H19*55%),0) -> 10373 | K19: 1500 | L19: 300 | M19: 200 | Q19: =SUM(H19:O19) -> 34062 | R19: =ROUND((H19*10%),0) -> 1886 | S19: 4500 | T19: =ROUND((H19*1%),0) -> 189 | AA19: 0 | AC19: 20 | AD19: 10 | AF19: =SUM(R19:AE19) -> 6605 | AG19: =Q19-AF19 -> 27457 | AH19: wRwc 18/48
B20: 13 | C20: 300046 | D20: ‡gvt eveyj wgqv µvdU BÝUªv±i ‡¯‹jt 11000-26590/- | E20: ‡gvt eveyj wgqv | F20: µvdU BÝUªv±i | G20: 0124100089728 | H20: 18860 | I20: =ROUND((H20*15%),0) -> 2829 | J20: =ROUND((H20*55%),0) -> 10373 | K20: 1500 | L20: 300 | M20: 200 | N20: 500 | Q20: =SUM(H20:O20) -> 34562 | R20: =ROUND((H20*10%),0) -> 1886 | S20: 5000 | T20: =ROUND((H20*1%),0) -> 189 | AA20: 0 | AC20: 20 | AD20: 10 | AF20: =SUM(R20:AE20) -> 7105 | AG20: =Q20-AF20 -> 27457 | AH20: wRwc 20/40
B21: 14 | C21: 300125 | D21: G.‡K.Gg.gymv evnv`yi µvdU BÝUªv±i ‡¯‹jt 11000-26590/- †hvM`vb : 18/05/2022 | E21: G.‡K.Gg.gymv evnv`yi | F21: µvdU BÝUªv±i | G21: 0124801018488 | H21: 12740 | I21: =ROUND((H21*15%),0) -> 1911 | J21: =ROUND((H21*60%),0) -> 7644 | K21: 1500 | L21: 300 | M21: 200 | Q21: =SUM(H21:O21) -> 24295 | R21: =ROUND((H21*10%),0) -> 1274 | T21: =ROUND((H21*1%),0) -> 127 | AC21: 20 | AD21: 10 | AF21: =SUM(R21:AE21) -> 1431 | AG21: =Q21-AF21 -> 22864
B22: 15 | C22: 300126 | D22: ‡gv: MvDmyj Bmjvg µvdU BÝUªv±i ‡¯‹jt 11000-26590/- †hvM`vb : 18/05/2022 | E22: ‡gv: MvDmyj Bmjvg | F22: µvdU BÝUªv±i | G22: 0124801018469 | H22: 12740 | I22: =ROUND((H22*15%),0) -> 1911 | J22: =ROUND((H22*60%),0) -> 7644 | K22: 1500 | L22: 300 | M22: 200 | Q22: =SUM(H22:O22) -> 24295 | R22: =ROUND((H22*10%),0) -> 1274 | T22: =ROUND((H22*1%),0) -> 127 | AC22: 20 | AD22: 10 | AF22: =SUM(R22:AE22) -> 1431 | AG22: =Q22-AF22 -> 22864
B23: 16 | C23: 300127 | D23: ‡gv: gvmy` µvdU BÝUªv±i ‡¯‹jt 11000-26590/- †hvM`vb : 18/05/2022 | E23: ‡gv: gvmy` | F23: µvdU BÝUªv±i | G23: 0124801018490 | H23: 12740 | I23: =ROUND((H23*15%),0) -> 1911 | J23: =ROUND((H23*60%),0) -> 7644 | K23: 1500 | L23: 300 | M23: 200 | Q23: =SUM(H23:O23) -> 24295 | R23: =ROUND((H23*10%),0) -> 1274 | T23: =ROUND((H23*1%),0) -> 127 | AC23: 20 | AD23: 10 | AF23: =SUM(R23:AE23) -> 1431 | AG23: =Q23-AF23 -> 22864
B24: 17 | C24: 300128 | D24: ‡gv: ivnvZ Av‡idxb µvdU BÝUªv±i ‡¯‹jt 11000-26590/- †hvM`vb : 18/05/2022 | E24: ‡gv: ivnvZ Av‡idxb | F24: µvdU BÝUªv±i | G24: 0124801018478 | H24: 12740 | I24: =ROUND((H24*15%),0) -> 1911 | J24: =ROUND((H24*60%),0) -> 7644 | K24: 1500 | L24: 300 | M24: 200 | N24: 500 | Q24: =SUM(H24:O24) -> 24795 | R24: =ROUND((H24*10%),0) -> 1274 | T24: =ROUND((H24*1%),0) -> 127 | AC24: 20 | AD24: 10 | AF24: =SUM(R24:AE24) -> 1431 | AG24: =Q24-AF24 -> 23364
B25: 18 | C25: 300129 | D25: ‡gv: wgRvbyi ingvb µvdU BÝUªv±i ‡¯‹jt 11000-26590/- †hvM`vb : 18/05/2022 | E25: ‡gv: wgRvbyi ingvb | F25: µvdU BÝUªv±i | G25: 0124801018485 | H25: 12740 | I25: =ROUND((H25*15%),0) -> 1911 | J25: =ROUND((H25*60%),0) -> 7644 | K25: 1500 | L25: 300 | M25: 200 | Q25: =SUM(H25:O25) -> 24295 | R25: =ROUND((H25*10%),0) -> 1274 | T25: =ROUND((H25*1%),0) -> 127 | AC25: 20 | AD25: 10 | AF25: =SUM(R25:AE25) -> 1431 | AG25: =Q25-AF25 -> 22864
B26: 19 | C26: 300130 | D26: ‡gv: nvweeyi ingvb µvdU BÝUªv±i ‡¯‹jt 11000-26590/- †hvM`vb : 18/05/2022 | E26: ‡gv: nvweeyi ingvb | F26: µvdU BÝUªv±i | G26: 0124801018487 | H26: 12740 | I26: =ROUND((H26*15%),0) -> 1911 | J26: =ROUND((H26*60%),0) -> 7644 | K26: 1500 | L26: 300 | M26: 200 | Q26: =SUM(H26:O26) -> 24295 | R26: =ROUND((H26*10%),0) -> 1274 | T26: =ROUND((H26*1%),0) -> 127 | AC26: 20 | AD26: 10 | AF26: =SUM(R26:AE26) -> 1431 | AG26: =Q26-AF26 -> 22864
B27: 20 | C27: 300131 | D27: wjsKz `vm µvdU BÝUªv±i ‡¯‹jt 11000-26590/- †hvM`vb : 18/05/2022 | E27: wjsKz `vm | F27: µvdU BÝUªv±i | G27: 0124801018481 | H27: 12740 | I27: =ROUND((H27*15%),0) -> 1911 | J27: =ROUND((H27*60%),0) -> 7644 | K27: 1500 | L27: 300 | M27: 200 | Q27: =SUM(H27:O27) -> 24295 | R27: =ROUND((H27*10%),0) -> 1274 | T27: =ROUND((H27*1%),0) -> 127 | AA27: 250 | AC27: 20 | AD27: 10 | AF27: =SUM(R27:AE27) -> 1681 | AG27: =Q27-AF27 -> 22614
B28: 21 | C28: 300132 | D28: Avãyjøvn Avj Iqvnx` µvdU BÝUªv±i ‡¯‹jt 11000-26590/- †hvM`vb : 18/05/2022 | E28: Avãyjøvn Avj Iqvnx` | F28: µvdU BÝUªv±i | G28: 0124801018507 | H28: 12740 | I28: =ROUND((H28*15%),0) -> 1911 | J28: =ROUND((H28*60%),0) -> 7644 | K28: 1500 | L28: 300 | M28: 200 | Q28: =SUM(H28:O28) -> 24295 | R28: =ROUND((H28*10%),0) -> 1274 | T28: =ROUND((H28*1%),0) -> 127 | AC28: 20 | AD28: 10 | AF28: =SUM(R28:AE28) -> 1431 | AG28: =Q28-AF28 -> 22864
B29: 22 | C29: 300133 | D29: dqmvj ingvb µvdU BÝUªv±i ‡¯‹jt 11000-26590/- †hvM`vb : 18/05/2022 | E29: dqmvj ingvb | F29: µvdU BÝUªv±i | G29: 0124801018466 | H29: 12740 | I29: =ROUND((H29*15%),0) -> 1911 | J29: =ROUND((H29*60%),0) -> 7644 | K29: 1500 | L29: 300 | M29: 200 | Q29: =SUM(H29:O29) -> 24295 | R29: =ROUND((H29*10%),0) -> 1274 | T29: =ROUND((H29*1%),0) -> 127 | AC29: 20 | AD29: 10 | AF29: =SUM(R29:AE29) -> 1431 | AG29: =Q29-AF29 -> 22864
B30: 23 | C30: 300134 | D30: Avd‡ivRv LvZzb wjRv µvdU BÝUªv±i ‡¯‹jt 11000-26590/- †hvM`vb : 18/05/2022 | E30: Avd‡ivRv LvZzb wjRv | F30: µvdU BÝUªv±i | G30: 0124100053268 | H30: 12740 | I30: =ROUND((H30*15%),0) -> 1911 | J30: =ROUND((H30*60%),0) -> 7644 | K30: 1500 | L30: 300 | M30: 200 | N30: 500 | Q30: =SUM(H30:O30) -> 24795 | R30: =ROUND((H30*10%),0) -> 1274 | T30: =ROUND((H30*1%),0) -> 127 | AC30: 20 | AD30: 10 | AF30: =SUM(R30:AE30) -> 1431 | AG30: =Q30-AF30 -> 23364
B31: 24 | C31: 300040 | D31: ‡gvt Ave`yj Avjxg µvdU BÝUªv±i ‡¯‹jt 11000-26590/- | E31: ‡gvt Ave`yj Avjxg | F31: µvdU BÝUªv±i | G31: 0124100087811 | H31: 18860 | I31: =ROUND((H31*15%),0) -> 2829 | K31: 1500 | L31: 300 | M31: 200 | N31: 1000 | Q31: =SUM(H31:O31) -> 24689 | R31: =ROUND((H31*10%),0) -> 1886 | S31: 4200 | T31: =ROUND((H31*1%),0) -> 189 | W31: 1080 | X31: 30 | Y31: 10 | Z31: 1730 | AA31: 0 | AC31: 20 | AD31: 10 | AF31: =SUM(R31:AE31) -> 9155 | AG31: =Q31-AF31 -> 15534 | AH31: wRwc 11/48
B32: 25 | C32: 300045 | D32: ‡gvt mvnv`vr †nv‡mb g„av µvdU BÝUªv±i ‡¯‹jt 11000-26590/- | E32: ‡gvt mvnv`vr †nv‡mb g„av | F32: µvdU BÝUªv±i | G32: 0124100066786 | H32: 18860 | I32: =ROUND((H32*15%),0) -> 2829 | J32: =ROUND((H32*55%),0) -> 10373 | K32: 1500 | L32: 300 | M32: 200 | N32: 500 | Q32: =SUM(H32:O32) -> 34562 | R32: =ROUND((H32*10%),0) -> 1886 | T32: =ROUND((H32*1%),0) -> 189 | AC32: 20 | AD32: 10 | AF32: =SUM(R32:AE32) -> 2105 | AG32: =Q32-AF32 -> 32457
B33: 26 | C33: 300075 | D33: ‡gvt Ryev‡qi Avn‡g` µvdU BÝUªv±i †¯‹jt 11000-26590/- | E33: ‡gvt Ryyev‡qi Avn‡g` | F33: ¯‹xì IqvK©vi | G33: 0124100091818 | H33: 14050 | I33: =ROUND((H33*15%),0) -> 2108 | J33: =ROUND((H33*60%),0) -> 8430 | K33: 1500 | L33: 300 | M33: 200 | N33: 500 | Q33: =SUM(H33:O33) -> 27088 | R33: =ROUND((H33*10%),0) -> 1405 | S33: 2100 | T33: =ROUND((H33*1%),0) -> 141 | AA33: 0 | AC33: 20 | AD33: 10 | AF33: =SUM(R33:AE33) -> 3676 | AG33: =Q33-AF33 -> 23412 | AH33: wRwc 13/48
B34: 27 | C34: 300078 | D34: ‡gvt wejøvj †nv‡mb µvdU BÝUªv±i †¯‹jt 11000-26590/- | E34: ‡gvt wejøvj †nv‡mb | F34: ¯‹xì IqvK©vi | G34: 0124801012558 | H34: 14050 | I34: =ROUND((H34*15%),0) -> 2108 | J34: =ROUND((H34*60%),0) -> 8430 | K34: 1500 | L34: 300 | M34: 200 | N34: 500 | Q34: =SUM(H34:P34) -> 27088 | R34: =ROUND((H34*10%),0) -> 1405 | T34: =ROUND((H34*1%),0) -> 141 | V34: 0 | W34: 0 | X34: 0 | Y34: 0 | AA34: 0 | AC34: 20 | AD34: 10 | AF34: =SUM(R34:AE34) -> 1576 | AG34: =Q34-AF34 -> 25512
B35: 28 | C35: 300081 | D35: ‡gvt gvnvgy`yj nvQvb f‚Bqv µvdU BÝUªv±i †¯‹jt 11000-26590/- | E35: ‡gvt gvnvgy`yj nvQvb f~Bqv | F35: ¯‹xì IqvK©vi | G35: 0124801013415 | H35: 13380 | I35: =ROUND((H35*15%),0) -> 2007 | K35: 1500 | L35: 300 | M35: 200 | Q35: =SUM(H35:O35) -> 17387 | R35: =ROUND((H35*10%),0) -> 1338 | T35: =ROUND((H35*1%),0) -> 134 | W35: 1080 | X35: 30 | Y35: 10 | Z35: 783 | AC35: 20 | AD35: 10 | AF35: =SUM(R35:AE35) -> 3405 | AG35: =Q35-AF35 -> 13982
B36: 29 | C36: 300095 | D36: ‡gvt Avey gvmyg miKvi µvdU BÝUªv±i †¯‹jt 11000-26590/- | E36: ‡gvt Avey gvmyg miKvi | F36: ¯‹xì IqvK©vi | G36: 0124801012879 | H36: 12130 | I36: =ROUND((H36*15%),0) -> 1820 | K36: 1500 | L36: 300 | M36: 200 | Q36: =SUM(H36:O36) -> 15950 | R36: =ROUND((H36*10%),0) -> 1213 | T36: =ROUND((H36*1%),0) -> 121 | W36: 1080 | X36: 30 | Y36: 10 | Z36: 1642 | AC36: 20 | AD36: 10 | AF36: =SUM(R36:AE36) -> 4126 | AG36: =Q36-AF36 -> 11824
B37: 30 | C37: 300090 | D37: Rbve †gvt Avwgbyj Bmjvg µvdU BÝUªv±i †¯‹jt 11000-26590/- | E37: ‡gvt Avwgbyj Bmjvg | F37: ¯‹xì IqvK©vi | G37: 0124801013432 | H37: 12130 | I37: =ROUND((H37*15%),0) -> 1820 | J37: =ROUND((H37*60%),0) -> 7278 | K37: 1500 | L37: 300 | M37: 200 | N37: 1000 | Q37: =SUM(H37:O37) -> 24228 | R37: =ROUND((H37*10%),0) -> 1213 | S37: 2000 | T37: =ROUND((H37*1%),0) -> 121 | AC37: 20 | AD37: 10 | AF37: =SUM(R37:AE37) -> 3364 | AG37: =Q37-AF37 -> 20864 | AH37: wRwc 19/45
B38: 31 | C38: 300121 | D38: †gvt Avwgbyi ingvb µvdU BÝUªv±i †¯‹jt 11000-26590/- | E38: ‡gvt Avwgbyj ingvb | F38: ¯‹xì IqvK©vi | G38: 0124801013297 | H38: 12130 | I38: =ROUND((H38*15%),0) -> 1820 | J38: =ROUND((H38*60%),0) -> 7278 | K38: 1500 | L38: 300 | M38: 200 | Q38: =SUM(H38:O38) -> 23228 | R38: =ROUND((H38*10%),0) -> 1213 | T38: =ROUND((H38*1%),0) -> 121 | AC38: 20 | AD38: 10 | AF38: =SUM(R38:AE38) -> 1364 | AG38: =Q38-AF38 -> 21864
B39: 32 | C39: 300048 | D39: nvwmqv Av³vi Awdm mnvqK †MªW-1 ‡¯‹j t 11000-26590/- | E39: nvwmqv Av³vi | F39: Awdm mnvqK †MªW-1 | G39: 0124100063757 | H39: 18860 | I39: =ROUND((H39*15%),0) -> 2829 | J39: 0 | K39: 1500 | L39: 300 | M39: 200 | N39: 500 | Q39: =SUM(H39:O39) -> 24189 | R39: =ROUND((H39*10%),0) -> 1886 | T39: =ROUND((H39*1%),0) -> 189 | V39: 0 | W39: 1080 | X39: 30 | Y39: 10 | Z39: 1905 | AA39: 0 | AC39: 20 | AD39: 10 | AF39: =SUM(R39:AE39) -> 5130 | AG39: =Q39-AF39 -> 19059
B40: 33 | C40: 300094 | D40: Av‡kKzj Bmjvg wnmveiÿK ‡¯‹j t 11000-26590/- | E40: Av‡kKzj Bmjvg | F40: wnmveiÿK | G40: 0124801014654 | H40: 13380 | I40: =ROUND((H40*15%),0) -> 2007 | J40: =ROUND((H40*60%),0) -> 8028 | K40: 1500 | L40: 300 | M40: 200 | N40: 500 | Q40: =SUM(H40:O40) -> 25915 | R40: =ROUND((H40*10%),0) -> 1338 | S40: 2500 | T40: =ROUND((H40*1%),0) -> 134 | AC40: 20 | AD40: 10 | AF40: =SUM(R40:AE40) -> 4002 | AG40: =Q40-AF40 -> 21913 | AH40: wRwc 16/40
B41: 34 | C41: 300117 | D41: kviwgb Av³vi ¯‹xì IqvK©vi †¯‹j t 11000-26590/- | E41: kviwgb Av³vi | F41: ¯‹xì IqvK©vi | G41: 0124801015596 | H41: 12740 | I41: =ROUND((H41*15%),0) -> 1911 | J41: =ROUND((H41*60%),0) -> 7644 | K41: 1500 | L41: 300 | M41: 200 | N41: 1000 | Q41: =SUM(H41:O41) -> 25295 | R41: =ROUND((H41*10%),0) -> 1274 | T41: =ROUND((H41*1%),0) -> 127 | AC41: 20 | AD41: 10 | AF41: =SUM(R41:AE41) -> 1431 | AG41: =Q41-AF41 -> 23864
...

Sheet Sheet5
A1: evsjv‡`k †U·UvBj wek¦we`¨vjq A_© I wnmve `ßi ‡ZRMuvI, XvKv - 1208|
A3: Gm.Avi.I bs 348-AvBb/2026, ZvwiL -17-9-2026 RvZxq †eZb †¯‹j 2026 Abyhvqx †eZb wba©vibx weeiYx t
B5: AvBwW | D5: 218
A6: 1 | B6: bvg | C6: t | D6: =VLOOKUP(D5,Inforation!A2:G412,2,FALSE) -> ‡gvt mvnv`vZ †nv‡mb
A7: 2 | B7: eZ©gvb c` (30-06-2026) | C7: t | D7: =VLOOKUP(D6,Inforation!B2:G412,2,FALSE) -> †mKkb Awdmvi
A8: 3 | B8: ey‡U· G †hvM`v‡bi ZvwiL | C8: t
A9: 4 | B9: wefvM/`ßi | C9: t | D9: =VLOOKUP(D6,Inforation!B2:G412,3,FALSE) -> A_© I wnmve
A10: 5 | B10: ‡mj †dvb bs | C10: t | D10: =VLOOKUP(D6,Inforation!B2:G413,4,FALSE) -> 0
A11: 6 | B11: RvZxq cwiPq cÎ bs | C11: t | D11: =VLOOKUP(D6,Inforation!B2:G414,5,FALSE) -> 0124100063454
A12: 7 | B12: wUAvBGb bs | C12: t
A13: 8 | B13: RvZxq †eZb †¯‹j 2015 Abyhvqx 30 Ryb 2026 Zvwi‡L M„nxZ †eZb | C13: t | D13: =VLOOKUP('Fixation '!D6,Inforation!B2:G413,6,FALSE) -> 28100
A14: 9 | B14: RvZxq †eZb †¯‹j 2015 Abyhvqx 30 Ryb 2026 Zvwi‡L | C14: t
B15: K) cÖvß †MÖW/D”PZi †MÖW I †¯‹j | C15: t | D15: গ্রেড - ৭
B16: L) cvß †MÖW/D”PZi †MÖ‡Wi cÖviw¤¢K ‡eZb | C16: t | D16: 22000
